Workbook

Sheet Income Statement
A1: DENISON MINES CORP (DNN / DML.TO)
A2: Consolidated Income Statement (CAD $000s)
A3: Source: 2024 Annual Report (40-F), Q3 2025 Interim Report
B5: FY 2022 | C5: FY 2023 | D5: FY 2024 | E5: Q3 2025 YTD | F5: LTM
A6: Revenue
A7: Uranium Sales
A8: Management Fee Revenue
A9: Toll Milling Revenue
A10: Total Revenue | B10: 2800 | C10: 1855 | D10: 4023 | E10: 8500
A11: Operating Expenses | G11: Source: Company 40-F, FY2024
A12: Exploration & Evaluation | B12: 12500 | C12: 15200 | D12: 18400 | E12: 14000
A13: Mine & Mill Operations | B13: 8200 | C13: 10500 | D13: 14800 | E13: 12500
A14: General & Administrative | B14: 15800 | C14: 18200 | D14: 22300 | E14: 17500
A15: Stock-Based Compensation | B15: 3500 | C15: 2956 | D15: 7031 | E15: 5200
A16: Total Operating Expenses | B16: =SUM(B12:B15) | C16: =SUM(C12:C15) | D16: =SUM(D12:D15) | E16: =SUM(E12:E15)
A18: Operating Income (Loss) | B18: =B10-B16 | C18: =C10-C16 | D18: =D10-D16 | E18: =E10-E16
A20: Other Income (Expense)
A21: Fair Value Gain/(Loss) on Investments | B21: -5200 | C21: 85000 | D21: -42000 | E21: -15000
A22: Interest Income | B22: 3800 | C22: 5200 | D22: 7800 | E22: 6200
A23: Interest Expense | B23: 0 | C23: 0 | D23: -11000 | E23: -11000
A24: Foreign Exchange Gain/(Loss) | B24: 1200 | C24: -800 | D24: -2500 | E24: 1800
A25: Other Income/(Expense) | B25: 500 | C25: 764 | D25: -1889 | E25: -3000
A26: Total Other Income (Expense) | B26: =SUM(B21:B25) | C26: =SUM(C21:C25) | D26: =SUM(D21:D25) | E26: =SUM(E21:E25)
A28: Income (Loss) Before Tax | B28: =B18+B26 | C28: =C18+C26 | D28: =D18+D26 | E28: =E18+E26
A29: Income Tax Expense (Recovery) | B29: 0 | C29: 0 | D29: 0 | E29: 0
A31: NET INCOME (LOSS) | B31: =B28-B29 | C31: =C28-C29 | D31: =D28-D29 | E31: =E28-E29
A33: Shares Outstanding (M) | B33: 855 | C33: 870 | D33: 890 | E33: 897.2
A34: EPS (Basic) (CAD) | B34: =B31/B33 | C34: =C31/C33 | D34: =D31/D33 | E34: =E31/E33
A36: Key Margins
A37: Operating Margin | B37: =IF(B10=0,0,B18/B10) | C37: =IF(C10=0,0,C18/C10) | D37: =IF(D10=0,0,D18/D10) | E37: =IF(E10=0,0,E18/E10)
A38: Net Margin | B38: =IF(B10=0,0,B31/B10) | C38: =IF(C10=0,0,C31/C10) | D38: =IF(D10=0,0,D31/D10) | E38: =IF(E10=0,0,E31/E10)
A39: YoY Revenue Growth | C39: =IF(B10=0,0,(C10-B10)/B10) | D39: =IF(C10=0,0,(D10-C10)/C10) | E39: =IF(D10=0,0,(E10-D10)/D10)

Sheet Balance Sheet
A1: DENISON MINES CORP (DNN / DML.TO)
A2: Consolidated Balance Sheet (CAD $000s)
A3: Source: 2024 Annual Report (40-F), Q3 2025 Interim Report
B5: Dec 31, 2023 | C5: Dec 31, 2024 | D5: Sep 30, 2025
A6: ASSETS
A7: Current Assets
A8: Cash & Cash Equivalents | B8: 180000 | C8: 195000 | D8: 285000
A9: Short-Term Investments | B9: 85000 | C9: 72000 | D9: 68000
A10: Physical Uranium Inventory | B10: 120000 | C10: 165000 | D10: 310000
A11: Trade & Other Receivables | B11: 8500 | C11: 12900 | D11: 15500
A12: Prepaid Expenses & Other | B12: 5500 | C12: 5000 | D12: 6200
A13: Investments in Uranium Purchase Commitments | B13: 30000 | C13: 50000 | D13: 35000
A14: Total Current Assets | B14: =SUM(B8:B13) | C14: =SUM(C8:C13) | D14: =SUM(D8:D13)
A16: Non-Current Assets
A17: Property, Plant & Equipment | B17: 185000 | C17: 210000 | D17: 285000
A18: Mineral Properties | B18: 220000 | C18: 245000 | D18: 260000
A19: Equity-Accounted Investments | B19: 95000 | C19: 110000 | D19: 125000
A20: Restricted Cash & Other | B20: 15000 | C20: 18000 | D20: 22000
A21: Goodwill & Intangibles | B21: 5000 | C21: 5000 | D21: 5000
A22: Total Non-Current Assets | B22: =SUM(B17:B21) | C22: =SUM(C17:C21) | D22: =SUM(D17:D21)
A24: TOTAL ASSETS | B24: =B14+B22 | C24: =C14+C22 | D24: =D14+D22
A26: LIABILITIES & EQUITY
A27: Current Liabilities
A28: Accounts Payable & Accrued Liabilities | B28: 18500 | C28: 25800 | D28: 32000
A29: Current Portion of Lease Liabilities | B29: 2800 | C29: 3200 | D29: 3500
A30: Deferred Revenue | B30: 5000 | C30: 8500 | D30: 6300
A31: Other Current Liabilities | B31: 2500 | C31: 4300 | D31: 5200
A32: Total Current Liabilities | B32: =SUM(B28:B31) | C32: =SUM(C28:C31) | D32: =SUM(D28:D31)
A34: Non-Current Liabilities
A35: Convertible Senior Notes (US$345M) | B35: 0 | C35: 0 | D35: 469000
A36: Long-Term Lease Liabilities | B36: 12000 | C36: 14500 | D36: 18000
A37: Decommissioning & Reclamation Provisions | B37: 45000 | C37: 52000 | D37: 58000
A38: Deferred Tax Liabilities | B38: 85000 | C38: 96000 | D38: 105000
A39: Other Non-Current Liabilities | B39: 8000 | C39: 12000 | D39: 15000
A40: Total Non-Current Liabilities | B40: =SUM(B35:B39) | C40: =SUM(C35:C39) | D40: =SUM(D35:D39)
A42: Total Liabilities | B42: =B32+B40 | C42: =C32+C40 | D42: =D32+D40
A44: Shareholders' Equity
A45: Share Capital | B45: 1150000 | C45: 1200000 | D45: 1250000
A46: Contributed Surplus | B46: 85000 | C46: 92000 | D46: 97000
A47: Accumulated Other Comprehensive Income | B47: 12000 | C47: 15000 | D47: 18000
...

Sheet Cash Flow Statement
A1: DENISON MINES CORP (DNN / DML.TO)
A2: Consolidated Cash Flow Statement (CAD $000s)
B4: FY 2022 | C4: FY 2023 | D4: FY 2024
A5: CASH FLOWS FROM OPERATING ACTIVITIES
A6: Net Income (Loss) | B6: ='Income Statement'!B31 | C6: ='Income Statement'!C31 | D6: ='Income Statement'!D31
A7: Adjustments:
A8: Depreciation & Amortization | B8: 5200 | C8: 6100 | D8: 7170
A9: Stock-Based Compensation | B9: 3500 | C9: 2956 | D9: 7031
A10: Fair Value (Gain)/Loss on Investments | B10: 5200 | C10: -85000 | D10: 42000
A11: Deferred Income Tax | B11: 2000 | C11: 8000 | D11: 11000
A12: Unrealized Foreign Exchange (Gain)/Loss | B12: -800 | C12: 600 | D12: 1500
A13: Other Non-Cash Items | B13: 1200 | C13: 1500 | D13: 2800
A14: Changes in Working Capital:
A15: Receivables | B15: -2500 | C15: -1200 | D15: -4400
A16: Uranium Inventory | B16: -35000 | C16: -25000 | D16: -45000
A17: Payables & Accruals | B17: 4500 | C17: 3200 | D17: 7300
A18: Other Working Capital | B18: -1500 | C18: 2000 | D18: -3500
A19: Net Cash from Operating Activities | B19: =SUM(B6,B8:B13,B15:B18) | C19: =SUM(C6,C8:C13,C15:C18) | D19: =SUM(D6,D8:D13,D15:D18)
A21: CASH FLOWS FROM INVESTING ACTIVITIES
A22: Mineral Property Expenditures | B22: -45000 | C22: -55000 | D22: -75000
A23: Property, Plant & Equipment Purchases | B23: -8000 | C23: -12000 | D23: -25000
A24: Purchase of Investments | B24: -15000 | C24: -10000 | D24: -8000
A25: Proceeds from Sale of Investments | B25: 5000 | C25: 8000 | D25: 12000
A26: Purchase of Physical Uranium | B26: -80000 | C26: -60000 | D26: -90000
A27: Proceeds from Sale of Physical Uranium | B27: 45000 | C27: 35000 | D27: 50000
A28: Other Investing Activities | B28: -2000 | C28: -3000 | D28: -5000
A29: Net Cash from Investing Activities | B29: =SUM(B22:B28) | C29: =SUM(C22:C28) | D29: =SUM(D22:D28)
A31: CASH FLOWS FROM FINANCING ACTIVITIES
A32: Proceeds from Convertible Notes Issuance | B32: 0 | C32: 0 | D32: 0
A33: Proceeds from Share Issuances | B33: 25000 | C33: 18000 | D33: 15000
A34: Share Issuance Costs | B34: -1500 | C34: -1200 | D34: -900
A35: Lease Payments | B35: -2800 | C35: -3200 | D35: -3500
A36: Other Financing Activities | B36: -500 | C36: -800 | D36: -1200
A37: Net Cash from Financing Activities | B37: =SUM(B32:B36) | C37: =SUM(C32:C36) | D37: =SUM(D32:D36)
A39: Effect of Exchange Rates on Cash | B39: 500 | C39: -300 | D39: -800
A41: NET CHANGE IN CASH | B41: =B19+B29+B37+B39 | C41: =C19+C29+C37+C39 | D41: =D19+D29+D37+D39
A43: Cash, Beginning of Period | B43: 145000 | C43: 155000 | D43: 180000
A44: Cash, End of Period | B44: =B43+B41 | C44: =C43+C41 | D44: =D43+D41
A46: FREE CASH FLOW CALCULATION
A47: Cash from Operations | B47: =B19 | C47: =C19 | D47: =D19
...

Sheet DCF Model
A1: DENISON MINES CORP — Discounted Cash Flow Analysis
A2: 5-Year DCF with Terminal Value (CAD $000s unless noted)
A4: KEY ASSUMPTIONS
A5: Uranium Spot Price (USD/lb) | B5: 85 | C5: Source: UxC, March 2026
A6: Long-Term Uranium Price (USD/lb) | B6: 80 | C6: Assumption: contract price
A7: USD/CAD Exchange Rate | B7: 1.36 | C7: Source: Bank of Canada, March 2026
A8: Effective Uranium Price (CAD/lb) | B8: =B5*B7 | C8: Formula: =B5*B7
A9: Phoenix Annual Production (M lbs U3O8) | B9: 5.4 | C9: Source: Company PFS, 95% interest
A10: Phoenix Cash Cost (CAD/lb) | B10: 17 | C10: Source: Company PFS estimate
A11: McClean Lake Production Share (M lbs) | B11: 0.65 | C11: Source: Q3 2025 report (22.5% share)
A12: Discount Rate (WACC) | B12: 0.1 | C12: Assumption: 10% for development-stage miner
A13: Terminal Growth Rate | B13: 0.02 | C13: Assumption: long-term GDP growth
A14: Tax Rate | B14: 0.265 | C14: Saskatchewan combined rate
A15: Shares Outstanding (M) | B15: 897.2 | C15: Source: Company filings, Mar 2026
A16: Phoenix Capex Remaining (CAD $M) | B16: 600 | C16: Source: Company Class 2 estimate
A17: Phoenix Production Start Year | B17: 2028 | C17: Source: Company guidance, mid-2028
A19: PRODUCTION & REVENUE PROJECTIONS
B20: Year 1 2026E | C20: Year 2 2027E | D20: Year 3 2028E | E20: Year 4 2029E | F20: Year 5 2030E | G20: Terminal
A21: McClean Lake Production (M lbs) | B21: 0.65 | C21: 0.65 | D21: 0.65 | E21: 0.65 | F21: 0.65 | G21: 0.65
A22: Phoenix Production (M lbs) | B22: 0 | C22: 0 | D22: 2.7 | E22: 5.4 | F22: 5.4 | G22: 5.4
A23: Total Production (M lbs) | B23: =B21+B22 | C23: =C21+C22 | D23: =D21+D22 | E23: =E21+E22 | F23: =F21+F22 | G23: =G21+G22
A24: Revenue per lb (CAD) | B24: =$B$8 | C24: =$B$8 | D24: =$B$8 | E24: =$B$8 | F24: =$B$8 | G24: =$B$8
A25: Total Revenue (CAD $000s) | B25: =B23*B24*1000 | C25: =C23*C24*1000 | D25: =D23*D24*1000 | E25: =E23*E24*1000 | F25: =F23*F24*1000 | G25: =G23*G24*1000 | I25: Formula: =Total Production × Revenue per lb × 1000
A26: Cash Operating Costs (CAD $000s) | B26: =B23*$B$10*1000 | C26: =C23*$B$10*1000 | D26: =D23*$B$10*1000 | E26: =E23*$B$10*1000 | F26: =F23*$B$10*1000 | G26: =G23*$B$10*1000 | I26: Formula: =Total Production × Cash Cost/lb × 1000
A27: Gross Profit (CAD $000s) | B27: =B25-B26 | C27: =C25-C26 | D27: =D25-D26 | E27: =E25-E26 | F27: =F25-F26 | G27: =G25-G26 | I27: Formula: =Revenue - Operating Costs
A28: G&A Expenses (CAD $000s) | B28: 22000 | C28: 23000 | D28: 25000 | E28: 27000 | F28: 28000 | G28: 29000
A29: EBITDA (CAD $000s) | B29: =B27-B28 | C29: =C27-C28 | D29: =D27-D28 | E29: =E27-E28 | F29: =F27-F28 | G29: =G27-G28 | I29: Formula: =Gross Profit - G&A
A30: D&A (CAD $000s) | B30: 8000 | C30: 9000 | D30: 15000 | E30: 22000 | F30: 22000 | G30: 22000
A31: EBIT (CAD $000s) | B31: =B29-B30 | C31: =C29-C30 | D31: =D29-D30 | E31: =E29-E30 | F31: =F29-F30 | G31: =G29-G30 | I31: Formula: =EBITDA - D&A
A32: Taxes (CAD $000s) | B32: =MAX(0,B31*$B$14) | C32: =MAX(0,C31*$B$14) | D32: =MAX(0,D31*$B$14) | E32: =MAX(0,E31*$B$14) | F32: =MAX(0,F31*$B$14) | G32: =MAX(0,G31*$B$14) | I32: Formula: =MAX(0, EBIT × Tax Rate)
A33: NOPAT (CAD $000s) | B33: =B31-B32 | C33: =C31-C32 | D33: =D31-D32 | E33: =E31-E32 | F33: =F31-F32 | G33: =G31-G32 | I33: Formula: =EBIT - Taxes
A34: Plus: D&A | B34: =B30 | C34: =C30 | D34: =D30 | E34: =E30 | F34: =F30 | G34: =G30
A35: Less: Capex (CAD $000s) | B35: -120000 | C35: -250000 | D35: -200000 | E35: -30000 | F35: -25000 | G35: -25000
A36: Less: Change in Working Capital (CAD $000s) | B36: -5000 | C36: -8000 | D36: -10000 | E36: -5000 | F36: -3000 | G36: -3000
A37: UNLEVERED FREE CASH FLOW (CAD $000s) | B37: =B33+B34+B35+B36 | C37: =C33+C34+C35+C36 | D37: =D33+D34+D35+D36 | E37: =E33+E34+E35+E36 | F37: =F33+F34+F35+F36 | G37: =G33+G34+G35+G36 | I37: Formula: =NOPAT + D&A + Capex + ΔWC
A39: DCF VALUATION
A40: Discount Factor | B40: =1/(1+$B$12)^1 | C40: =1/(1+$B$12)^2 | D40: =1/(1+$B$12)^3 | E40: =1/(1+$B$12)^4 | F40: =1/(1+$B$12)^5 | I40: Formula: =1/(1+WACC)^Year
A41: PV of FCF | B41: =B37*B40 | C41: =C37*C40 | D41: =D37*D40 | E41: =E37*E40 | F41: =F37*F40 | I41: Formula: =UFCF × Discount Factor
A43: Sum of PV of FCFs | B43: =SUM(B41:F41) | I43: Formula: =SUM(PV of each year's FCF)
A44: Terminal Value (Gordon Growth) | B44: =G37*(1+$B$13)/($B$12-$B$13) | I44: Formula: =Terminal FCF × (1+g) / (WACC - g)
...

Sheet Valuation & Peer Comps
A1: DENISON MINES CORP — Valuation Summary & Peer Comparables
A3: NET ASSET VALUE (NAV) MODEL
A4: Asset / Liability | B4: Denison Share | C4: Value (CAD $M) | D4: Notes
A5: Phoenix Deposit (ISR) | B5: 95% | D5: PFS NPV8% at $85/lb U3O8
A6: Gross NPV8% (CAD $M) | C6: 3200 | D6: Source: Company PFS Update
A7: Less: Remaining Capex | C7: -600 | D7: Source: Company estimate
A8: Net Phoenix Value | C8: =C6+C7
A9: Gryphon Deposit | B9: 95% | C9: 800 | D9: Pre-feasibility estimate
A10: McClean Lake Mill (22.5%) | B10: 22.5% | C10: 350 | D10: Based on replacement cost
A11: Physical Uranium Holdings | B11: 100% | C11: =1.2*85*1.36 | D11: 1.2M lbs @ spot × FX
A12: Cash & Investments | B12: 100% | C12: 267 | D12: Source: Balance Sheet
A13: Other Mineral Properties | B13: 100% | C13: 150 | D13: Exploration assets at book
A14: Equity Investments (JCU etc.) | B14: 100% | C14: 125 | D14: Source: Balance Sheet
A15: Less: Convertible Notes | C15: -469 | D15: US$345M converted to CAD
A16: Less: Reclamation Provisions | C16: -58 | D16: Source: Balance Sheet
A17: Less: Other Net Liabilities | C17: -40 | D17: Source: Balance Sheet
A18: TOTAL NAV (CAD $M) | C18: =SUM(C8:C17) | I18: Formula: =SUM(all NAV components)
A19: NAV per Share (CAD) | C19: =C18/('DCF Model'!B15) | I19: Formula: =Total NAV / Shares Outstanding
A20: NAV per Share (USD) | C20: =C19/'DCF Model'!B7
A21: Current Price / NAV (P/NAV) | C21: =3.33/C20 | I21: Formula: =Current USD Price / NAV per share USD
A23: COMPARABLE COMPANY ANALYSIS
A24: Company | B24: Ticker | C24: Mkt Cap ($M) | D24: EV ($M) | E24: Revenue ($M) | F24: P/E | G24: EV/EBITDA | H24: P/Book
A25: Cameco Corp | B25: CCJ | C25: 49160 | D25: 46350 | E25: 3480 | F25: 110 | G25: 52 | H25: 5.8
A26: Uranium Energy Corp | B26: UEC | C26: 5930 | D26: 3560 | E26: 81 | H26: 4.2
A27: NexGen Energy | B27: NXE | C27: 7750 | D27: 7960 | H27: 13.1
A28: Energy Fuels | B28: UUUU | C28: 3950 | D28: 4970 | E28: 113 | H28: 3.5
A29: Ur-Energy | B29: URG | C29: 613 | D29: 580 | E29: 39 | H29: 3.2
A30: Denison Mines | B30: DNN | C30: 3187 | D30: =C30+'DCF Model'!B54/'DCF Model'!B7-('DCF Model'!B51+'DCF Model'!B52+'DCF Model'!B53)/'DCF Model'!B7 | E30: ='Income Statement'!E10/'DCF Model'!B7 | H30: =C30/('Balance Sheet'!D49/'DCF Model'!B7)
A31: Peer Average (excl. DNN) | C31: =AVERAGE(C25:C29) | D31: =AVERAGE(D25:D29) | H31: =AVERAGE(H25:H29)
A32: Peer Median (excl. DNN) | C32: =MEDIAN(C25:C29) | H32: =MEDIAN(H25:H29)
A34: P/NAV IMPLIED VALUATION
A35: Scenario | B35: P/NAV Multiple | C35: Implied Price (USD) | D35: Upside/Downside
A36: Bear Case (0.7x NAV) | B36: 0.7 | C36: =B36*$C$20 | D36: =(C36-3.33)/3.33 | I36: Formula: =P/NAV × NAV/share; Upside = (Implied - Current) / Current
A37: Base Case (1.0x NAV) | B37: 1 | C37: =B37*$C$20 | D37: =(C37-3.33)/3.33 | I37: Formula: =P/NAV × NAV/share; Upside = (Implied - Current) / Current
A38: Bull Case (1.3x NAV) | B38: 1.3 | C38: =B38*$C$20 | D38: =(C38-3.33)/3.33 | I38: Formula: =P/NAV × NAV/share; Upside = (Implied - Current) / Current
A39: Premium Case (1.5x NAV) | B39: 1.5 | C39: =B39*$C$20 | D39: =(C39-3.33)/3.33 | I39: Formula: =P/NAV × NAV/share; Upside = (Implied - Current) / Current
A41: EV / RESOURCE (lbs U3O8) VALUATION
A42: Company | B42: EV ($M USD) | C42: Resources (M lbs) | D42: EV/lb
A43: Cameco | B43: 46350 | C43: 455 | D43: =IF(C43=0,0,B43/C43)
A44: NexGen Energy | B44: 7960 | C44: 350 | D44: =IF(C44=0,0,B44/C44)
...
