Workbook

Sheet Team Info
A1: Team Number: | B1: 1
D2: Emphasis Company: | K2: Compare Company:
A3: Team Member Name: | B3: Email:
A4: Joel Applegate | B4: jaa9436@uncw.edu
A5: Joey Bridgham | B5: jjb3229@uncw.edu
A6: Owen Bieler | B6: orb1456@uncw.edu
A7: Taylor Chapman | B7: tlc3246@uncw.edu
A8: Colin Waltsak | B8: cpw9627@uncw.edu

Sheet D1_Balance Sheet
A1: Line Items | B1: Year(t=0) | C1: Year(t=-1) | D1: Year(t=-2) | E1: Year(t=-3) | F1: Year(t=-4) | G1: Year(t=-5) | J1: MEAN | K1: STD | L1: MIN | M1: MEDIAN | N1: MAX
B2: 2025 | C2: 2024 | D2: 2023 | E2: 2022 | F2: 2021 | G2: 2020
A3: Current Assets
A4: Cash and Cash Equivalents | B4: 23356 | C4: 22935 | D4: 24862 | E4: 25134 | F4: 20540 | G4: 25243 | J4: =AVERAGE(B4:G4) -> 23678.333 | K4: =STDEV(B4:G4) -> 1815.147 | L4: =MIN(B4:G4) -> 20540 | M4: =MEDIAN(B4:G4) -> 24109 | N4: =MAX(B4:G4) -> 25243
A5: Marketable Securities | B5: 15131 | C5: 15413 | D5: 15309 | E5: 18936 | F5: 29053 | G5: 24718 | J5: =AVERAGE(B5:G5) -> 19760 | K5: =STDEV(B5:G5) -> 5860.9904 | L5: =MIN(B5:G5) -> 15131 | M5: =MEDIAN(B5:G5) -> 17174.5 | N5: =MAX(B5:G5) -> 29053
A6: Trade and Other Receivables | B6: 15398 | C6: 14723 | D6: 15601 | E6: 15729 | F6: 11370 | G6: 9993 | J6: =AVERAGE(B6:G6) -> 13802.333 | K6: =STDEV(B6:G6) -> 2480.6568 | L6: =MIN(B6:G6) -> 9993 | M6: =MEDIAN(B6:G6) -> 15060.5 | N6: =MAX(B6:G6) -> 15729
A7: Inventories | B7: 15285 | C7: 14951 | D7: 15651 | E7: 14080 | F7: 12065 | G7: 10808 | J7: =AVERAGE(B7:G7) -> 13806.667 | K7: =STDEV(B7:G7) -> 1949.187 | L7: =MIN(B7:G7) -> 10808 | M7: =MEDIAN(B7:G7) -> 14515.5 | N7: =MAX(B7:G7) -> 15651
A8: Financial Services Finance Receivables, Net | B8: 49130 | C8: 51850 | D8: 46425 | E8: 38720 | F8: 32543 | G8: 42401 | J8: =AVERAGE(B8:G8) -> 43511.5 | K8: =STDEV(B8:G8) -> 7128.6223 | L8: =MIN(B8:G8) -> 32543 | M8: =MEDIAN(B8:G8) -> 44413 | N8: =MAX(B8:G8) -> 51850
A9: Asset Held for Sale | F9: 9 | J9: =AVERAGE(B9:G9) -> 9 | K9: =STDEV(B9:G9) -> #DIV/0! | L9: =MIN(B9:G9) -> 9 | M9: =MEDIAN(B9:G9) -> 9 | N9: =MAX(B9:G9) -> 9
A10: Other Current Assets | B10: 5187 | C10: 4602 | D10: 3633 | E10: 3877 | F10: 3416 | G10: 3581 | J10: =AVERAGE(B10:G10) -> 4049.3333 | K10: =STDEV(B10:G10) -> 696.16167 | L10: =MIN(B10:G10) -> 3416 | M10: =MEDIAN(B10:G10) -> 3755 | N10: =MAX(B10:G10) -> 5187
A11: Total Current Assets | B11: 123487 | C11: 124474 | D11: 121481 | E11: 116476 | F11: 108996 | G11: 116744 | J11: =AVERAGE(B11:G11) -> 118609.67 | K11: =STDEV(B11:G11) -> 5777.1822 | L11: =MIN(B11:G11) -> 108996 | M11: =MEDIAN(B11:G11) -> 119112.5 | N11: =MAX(B11:G11) -> 124474
A12: Noncurrent Assets
A13: Net Property | B13: 37288 | C13: 41928 | D13: 40821 | E13: 37265 | F13: 37139 | G13: 37083 | J13: =AVERAGE(B13:G13) -> 38587.333 | K13: =STDEV(B13:G13) -> 2188.4625 | L13: =MIN(B13:G13) -> 37083 | M13: =MEDIAN(B13:G13) -> 37276.5 | N13: =MAX(B13:G13) -> 41928
A14: Net Investment in Operating Leases | B14: 28540 | C14: 22947 | D14: 21384 | E14: 22772 | F14: 26361 | G14: 27951 | J14: =AVERAGE(B14:G14) -> 24992.5 | K14: =STDEV(B14:G14) -> 3011.519 | L14: =MIN(B14:G14) -> 21384 | M14: =MEDIAN(B14:G14) -> 24654 | N14: =MAX(B14:G14) -> 28540
A15: Equity in Net Assets of Affiliated Companies | B15: 2753 | C15: 6821 | D15: 5548 | E15: 2798 | F15: 4545 | G15: 4901 | J15: =AVERAGE(B15:G15) -> 4561 | K15: =STDEV(B15:G15) -> 1585.8536 | L15: =MIN(B15:G15) -> 2753 | M15: =MEDIAN(B15:G15) -> 4723 | N15: =MAX(B15:G15) -> 6821
A16: Deferred Income Taxes | B16: 21953 | C16: 16375 | D16: 16985 | E16: 15552 | F16: 13796 | G16: 12423 | J16: =AVERAGE(B16:G16) -> 16180.667 | K16: =STDEV(B16:G16) -> 3292.6119 | L16: =MIN(B16:G16) -> 12423 | M16: =MEDIAN(B16:G16) -> 15963.5 | N16: =MAX(B16:G16) -> 21953
A17: Ford Credit Finance Receivables, Net | B17: 61449 | C17: 59786 | D17: 55650 | E17: 49903 | F17: 51256 | G17: 55277 | J17: =AVERAGE(B17:G17) -> 55553.5 | K17: =STDEV(B17:G17) -> 4542.1008 | L17: =MIN(B17:G17) -> 49903 | M17: =MEDIAN(B17:G17) -> 55463.5 | N17: =MAX(B17:G17) -> 61449
A18: Other Assets | B18: 13690 | C18: 12865 | D18: 11441 | E18: 11118 | F18: 14942 | G18: 12882 | J18: =AVERAGE(B18:G18) -> 12823 | K18: =STDEV(B18:G18) -> 1418.7349 | L18: =MIN(B18:G18) -> 11118 | M18: =MEDIAN(B18:G18) -> 12873.5 | N18: =MAX(B18:G18) -> 14942
A19: Total Assets | B19: 289160 | C19: 285196 | D19: 273310 | E19: 255884 | F19: 257035 | G19: 267261 | J19: =AVERAGE(B19:G19) -> 271307.67 | K19: =STDEV(B19:G19) -> 13954.031 | L19: =MIN(B19:G19) -> 255884 | M19: =MEDIAN(B19:G19) -> 270285.5 | N19: =MAX(B19:G19) -> 289160
A20: Current Liabilities
A21: Company Excluding Ford Credit | B21: 5550 | C21: 1756 | D21: 477 | E21: 730 | F21: 3175 | G21: 1374 | J21: =AVERAGE(B21:G21) -> 2177 | K21: =STDEV(B21:G21) -> 1906.777 | L21: =MIN(B21:G21) -> 477 | M21: =MEDIAN(B21:G21) -> 1565 | N21: =MAX(B21:G21) -> 5550
A22: Ford Credit | J22: =AVERAGE(B22:G22) -> #DIV/0! | K22: =STDEV(B22:G22) -> #DIV/0! | L22: =MIN(B22:G22) -> 0 | M22: =MEDIAN(B22:G22) -> #NUM! | N22: =MAX(B22:G22) -> 0
A23: Ford Credit Debt Payable within One Year | B23: 51752 | C23: 53193 | D23: 49192 | E23: 49434 | F23: 46517 | G23: 49969 | J23: =AVERAGE(B23:G23) -> 50009.5 | K23: =STDEV(B23:G23) -> 2296.5052 | L23: =MIN(B23:G23) -> 46517 | M23: =MEDIAN(B23:G23) -> 49701.5 | N23: =MAX(B23:G23) -> 53193
A24: Payables | B24: 25809 | C24: 24128 | D24: 25992 | E24: 25605 | F24: 22349 | G24: 22204 | J24: =AVERAGE(B24:G24) -> 24347.833 | K24: =STDEV(B24:G24) -> 1735.4217 | L24: =MIN(B24:G24) -> 22204 | M24: =MEDIAN(B24:G24) -> 24866.5 | N24: =MAX(B24:G24) -> 25992
A25: Other Liabilities and Deferred Revenue | B25: 31779 | C25: 27782 | D25: 25870 | E25: 21097 | F25: 18686 | G25: 23645 | J25: =AVERAGE(B25:G25) -> 24809.833 | K25: =STDEV(B25:G25) -> 4715.3009 | L25: =MIN(B25:G25) -> 18686 | M25: =MEDIAN(B25:G25) -> 24757.5 | N25: =MAX(B25:G25) -> 31779
A26: Total Current Liabilities | B26: 114890 | C26: 106859 | D26: 101531 | E26: 96866 | F26: 90727 | G26: 97192 | J26: =AVERAGE(B26:G26) -> 101344.17 | K26: =STDEV(B26:G26) -> 8531.7828 | L26: =MIN(B26:G26) -> 90727 | M26: =MEDIAN(B26:G26) -> 99361.5 | N26: =MAX(B26:G26) -> 114890
A27: Noncurrent Liabilities
A28: Company Excluding Ford Credit | B28: 16369 | C28: 18898 | D28: 19467 | E28: 19200 | F28: 17200 | G28: 22633 | J28: =AVERAGE(B28:G28) -> 18961.167 | K28: =STDEV(B28:G28) -> 2173.49 | L28: =MIN(B28:G28) -> 16369 | M28: =MEDIAN(B28:G28) -> 19049 | N28: =MAX(B28:G28) -> 22633
A29: Deferred Income Taxes | B29: 1354 | C29: 1074 | D29: 1005 | E29: 1549 | F29: 1581 | G29: 538 | J29: =AVERAGE(B29:G29) -> 1183.5 | K29: =STDEV(B29:G29) -> 395.2694 | L29: =MIN(B29:G29) -> 538 | M29: =MEDIAN(B29:G29) -> 1214 | N29: =MAX(B29:G29) -> 1581
A30: Minority Interest | B30: 28 | C30: 23 | D30: 25 | E30: -75 | F30: 103 | G30: 121 | J30: =AVERAGE(B30:G30) -> 37.5 | K30: =STDEV(B30:G30) -> 69.821916 | L30: =MIN(B30:G30) -> -75 | M30: =MEDIAN(B30:G30) -> 26.5 | N30: =MAX(B30:G30) -> 121
A31: Ford Credit | J31: =AVERAGE(B31:G31) -> #DIV/0! | K31: =STDEV(B31:G31) -> #DIV/0! | L31: =MIN(B31:G31) -> 0 | M31: =MEDIAN(B31:G31) -> #NUM! | N31: =MAX(B31:G31) -> 0
A32: Ford Credit Long- Term Debt | B32: 89665 | C32: 84675 | D32: 80095 | E32: 69605 | F32: 71200 | G32: 87708 | J32: =AVERAGE(B32:G32) -> 80491.333 | K32: =STDEV(B32:G32) -> 8470.3921 | L32: =MIN(B32:G32) -> 69605 | M32: =MEDIAN(B32:G32) -> 82385 | N32: =MAX(B32:G32) -> 89665
A33: Other Liabilities and Deferred Revenue | B33: 30902 | C33: 28832 | D33: 28414 | E33: 25497 | F33: 27705 | G33: 28379 | J33: =AVERAGE(B33:G33) -> 28288.167 | K33: =STDEV(B33:G33) -> 1748.294 | L33: =MIN(B33:G33) -> 25497 | M33: =MEDIAN(B33:G33) -> 28396.5 | N33: =MAX(B33:G33) -> 30902
A34: Shareholders' Equity
A35: Common Stock - Par Value | B35: 1 | C35: 1 | D35: 1 | E35: 1 | F35: 1 | G35: 1 | J35: =AVERAGE(B35:G35) -> 1 | K35: =STDEV(B35:G35) -> 0 | L35: =MIN(B35:G35) -> 1 | M35: =MEDIAN(B35:G35) -> 1 | N35: =MAX(B35:G35) -> 1
A36: Common Stock - Par Value | B36: 41 | C36: 41 | D36: 41 | E36: 41 | F36: 40 | G36: 40 | J36: =AVERAGE(B36:G36) -> 40.666667 | K36: =STDEV(B36:G36) -> 0.51639778 | L36: =MIN(B36:G36) -> 40 | M36: =MEDIAN(B36:G36) -> 41 | N36: =MAX(B36:G36) -> 41
A37: Additional Paid in Capital | B37: 23922 | C37: 23502 | D37: 23128 | E37: 22832 | F37: 22611 | G37: 22290 | J37: =AVERAGE(B37:G37) -> 23047.5 | K37: =STDEV(B37:G37) -> 598.09355 | L37: =MIN(B37:G37) -> 22290 | M37: =MEDIAN(B37:G37) -> 22980 | N37: =MAX(B37:G37) -> 23922
A38: Treasury Stock - Common | B38: -2810 | C38: -2810 | D38: -2384 | E38: -2047 | F38: -1563 | G38: -1590 | J38: =AVERAGE(B38:G38) -> -2200.6667 | K38: =STDEV(B38:G38) -> 562.01981 | L38: =MIN(B38:G38) -> -2810 | M38: =MEDIAN(B38:G38) -> -2215.5 | N38: =MAX(B38:G38) -> -1563
A39: Retained Earnings | J39: =AVERAGE(B39:G39) -> #DIV/0! | K39: =STDEV(B39:G39) -> #DIV/0! | L39: =MIN(B39:G39) -> 0 | M39: =MEDIAN(B39:G39) -> #NUM! | N39: =MAX(B39:G39) -> 0
A40: Retained Earnings (Accumulated Deficit) | B40: 22508 | C40: 33740 | D40: 31029 | E40: 31754 | F40: 35769 | G40: 18243 | J40: =AVERAGE(B40:G40) -> 28840.5 | K40: =STDEV(B40:G40) -> 6894.8501 | L40: =MIN(B40:G40) -> 18243 | M40: =MEDIAN(B40:G40) -> 31391.5 | N40: =MAX(B40:G40) -> 35769
...

Sheet D2_BalanceSheetCommonSize
A1: Common Size balance sheet | B1: Year(t=0) | C1: Year(t=-1) | D1: Year(t=-2) | E1: Year(t=-3) | F1: Year(t=-4) | G1: Year(t=-5)
A2: % of Total assests = (line item/total assests)x100
B3: 2025 | C3: 2024 | D3: 2023 | E3: 2022 | F3: 2021 | G3: 2020
A4: Current Assets
A5: Cash and Cash Equivalents | B5: =('D1_Balance Sheet'!B4/'D1_Balance Sheet'!$B$19) -> 0.080771891 | C5: =('D1_Balance Sheet'!C4/'D1_Balance Sheet'!$C$19) -> 0.080418379 | D5: =('D1_Balance Sheet'!D4/'D1_Balance Sheet'!$D$19) -> 0.090966302 | E5: =('D1_Balance Sheet'!E4/'D1_Balance Sheet'!$E$19) -> 0.098224195 | F5: =('D1_Balance Sheet'!F4/'D1_Balance Sheet'!$F$19) -> 0.079911296 | G5: =('D1_Balance Sheet'!G4/'D1_Balance Sheet'!$G$19) -> 0.094450743
A6: Marketable Securities | B6: =('D1_Balance Sheet'!B5/'D1_Balance Sheet'!$B$19) -> 0.052327431 | C6: =('D1_Balance Sheet'!C5/'D1_Balance Sheet'!$C$19) -> 0.054043535 | D6: =('D1_Balance Sheet'!D5/'D1_Balance Sheet'!$D$19) -> 0.056013318 | E6: =('D1_Balance Sheet'!E5/'D1_Balance Sheet'!$E$19) -> 0.074002282 | F6: =('D1_Balance Sheet'!F5/'D1_Balance Sheet'!$F$19) -> 0.1130313 | G6: =('D1_Balance Sheet'!G5/'D1_Balance Sheet'!$G$19) -> 0.092486371
A7: Trade and Other Receivables | B7: =('D1_Balance Sheet'!B6/'D1_Balance Sheet'!$B$19) -> 0.053250795 | C7: =('D1_Balance Sheet'!C6/'D1_Balance Sheet'!$C$19) -> 0.051624146 | D7: =('D1_Balance Sheet'!D6/'D1_Balance Sheet'!$D$19) -> 0.057081702 | E7: =('D1_Balance Sheet'!E6/'D1_Balance Sheet'!$E$19) -> 0.06146926 | F7: =('D1_Balance Sheet'!F6/'D1_Balance Sheet'!$F$19) -> 0.044235221 | G7: =('D1_Balance Sheet'!G6/'D1_Balance Sheet'!$G$19) -> 0.037390416
A8: Inventories | B8: =('D1_Balance Sheet'!B7/'D1_Balance Sheet'!$B$19) -> 0.052860008 | C8: =('D1_Balance Sheet'!C7/'D1_Balance Sheet'!$C$19) -> 0.052423596 | D8: =('D1_Balance Sheet'!D7/'D1_Balance Sheet'!$D$19) -> 0.057264645 | E8: =('D1_Balance Sheet'!E7/'D1_Balance Sheet'!$E$19) -> 0.055024933 | F8: =('D1_Balance Sheet'!F7/'D1_Balance Sheet'!$F$19) -> 0.046939133 | G8: =('D1_Balance Sheet'!G7/'D1_Balance Sheet'!$G$19) -> 0.04043987
A9: Financial Services Finance Receivables, Net | B9: =('D1_Balance Sheet'!B8/'D1_Balance Sheet'!$B$19) -> 0.16990593 | C9: =('D1_Balance Sheet'!C8/'D1_Balance Sheet'!$C$19) -> 0.18180479 | D9: =('D1_Balance Sheet'!D8/'D1_Balance Sheet'!$D$19) -> 0.16986206 | E9: =('D1_Balance Sheet'!E8/'D1_Balance Sheet'!$E$19) -> 0.15131857 | F9: =('D1_Balance Sheet'!F8/'D1_Balance Sheet'!$F$19) -> 0.12660922 | G9: =('D1_Balance Sheet'!G8/'D1_Balance Sheet'!$G$19) -> 0.15865016
A10: Asset Held for Sale | B10: =('D1_Balance Sheet'!B9/'D1_Balance Sheet'!$B$19) -> 0 | C10: =('D1_Balance Sheet'!C9/'D1_Balance Sheet'!$C$19) -> 0 | D10: =('D1_Balance Sheet'!D9/'D1_Balance Sheet'!$D$19) -> 0 | E10: =('D1_Balance Sheet'!E9/'D1_Balance Sheet'!$E$19) -> 0 | F10: =('D1_Balance Sheet'!F9/'D1_Balance Sheet'!$F$19) -> 3.5014687e-05 | G10: =('D1_Balance Sheet'!G9/'D1_Balance Sheet'!$G$19) -> 0
A11: Other Current Assets | B11: =('D1_Balance Sheet'!B10/'D1_Balance Sheet'!$B$19) -> 0.017938166 | C11: =('D1_Balance Sheet'!C10/'D1_Balance Sheet'!$C$19) -> 0.016136271 | D11: =('D1_Balance Sheet'!D10/'D1_Balance Sheet'!$D$19) -> 0.013292598 | E11: =('D1_Balance Sheet'!E10/'D1_Balance Sheet'!$E$19) -> 0.015151397 | F11: =('D1_Balance Sheet'!F10/'D1_Balance Sheet'!$F$19) -> 0.013290019 | G11: =('D1_Balance Sheet'!G10/'D1_Balance Sheet'!$G$19) -> 0.013398887
A12: Total Current Assets | B12: =('D1_Balance Sheet'!B11/'D1_Balance Sheet'!$B$19) -> 0.42705423 | C12: =('D1_Balance Sheet'!C11/'D1_Balance Sheet'!$C$19) -> 0.43645072 | D12: =('D1_Balance Sheet'!D11/'D1_Balance Sheet'!$D$19) -> 0.44448063 | E12: =('D1_Balance Sheet'!E11/'D1_Balance Sheet'!$E$19) -> 0.45519063 | F12: =('D1_Balance Sheet'!F11/'D1_Balance Sheet'!$F$19) -> 0.4240512 | G12: =('D1_Balance Sheet'!G11/'D1_Balance Sheet'!$G$19) -> 0.43681645
A13: Noncurrent Assets | B13: =('D1_Balance Sheet'!B12/'D1_Balance Sheet'!$B$19) -> 0 | C13: =('D1_Balance Sheet'!C12/'D1_Balance Sheet'!$C$19) -> 0 | D13: =('D1_Balance Sheet'!D12/'D1_Balance Sheet'!$D$19) -> 0 | E13: =('D1_Balance Sheet'!E12/'D1_Balance Sheet'!$E$19) -> 0 | F13: =('D1_Balance Sheet'!F12/'D1_Balance Sheet'!$F$19) -> 0 | G13: =('D1_Balance Sheet'!G12/'D1_Balance Sheet'!$G$19) -> 0
A14: Net Property | B14: =('D1_Balance Sheet'!B13/'D1_Balance Sheet'!$B$19) -> 0.12895283 | C14: =('D1_Balance Sheet'!C13/'D1_Balance Sheet'!$C$19) -> 0.14701468 | D14: =('D1_Balance Sheet'!D13/'D1_Balance Sheet'!$D$19) -> 0.14935787 | E14: =('D1_Balance Sheet'!E13/'D1_Balance Sheet'!$E$19) -> 0.1456324 | F14: =('D1_Balance Sheet'!F13/'D1_Balance Sheet'!$F$19) -> 0.14449005 | G14: =('D1_Balance Sheet'!G13/'D1_Balance Sheet'!$G$19) -> 0.13875201
A15: Net Investment in Operating Leases | B15: =('D1_Balance Sheet'!B14/'D1_Balance Sheet'!$B$19) -> 0.098699682 | C15: =('D1_Balance Sheet'!C14/'D1_Balance Sheet'!$C$19) -> 0.080460455 | D15: =('D1_Balance Sheet'!D14/'D1_Balance Sheet'!$D$19) -> 0.078240825 | E15: =('D1_Balance Sheet'!E14/'D1_Balance Sheet'!$E$19) -> 0.08899345 | F15: =('D1_Balance Sheet'!F14/'D1_Balance Sheet'!$F$19) -> 0.10255802 | G15: =('D1_Balance Sheet'!G14/'D1_Balance Sheet'!$G$19) -> 0.10458316
A16: Equity in Net Assets of Affiliated Companies | B16: =('D1_Balance Sheet'!B15/'D1_Balance Sheet'!$B$19) -> 0.0095206806 | C16: =('D1_Balance Sheet'!C15/'D1_Balance Sheet'!$C$19) -> 0.023916885 | D16: =('D1_Balance Sheet'!D15/'D1_Balance Sheet'!$D$19) -> 0.020299294 | E16: =('D1_Balance Sheet'!E15/'D1_Balance Sheet'!$E$19) -> 0.010934642 | F16: =('D1_Balance Sheet'!F15/'D1_Balance Sheet'!$F$19) -> 0.017682417 | G16: =('D1_Balance Sheet'!G15/'D1_Balance Sheet'!$G$19) -> 0.018337879
... A22: Company Excluding Ford Credit | B22: =('D1_Balance Sheet'!B21/'D1_Balance Sheet'!$B$19) -> 0.019193526 | C22: =('D1_Balance Sheet'!C21/'D1_Balance Sheet'!$C$19) -> 0.0061571691 | D22: =('D1_Balance Sheet'!D21/'D1_Balance Sheet'!$D$19) -> 0.0017452709 | E22: =('D1_Balance Sheet'!E21/'D1_Balance Sheet'!$E$19) -> 0.0028528552 | F22: =('D1_Balance Sheet'!F21/'D1_Balance Sheet'!$F$19) -> 0.012352403 | G22: =('D1_Balance Sheet'!G21/'D1_Balance Sheet'!$G$19) -> 0.0051410419
A23: Ford Credit | B23: =('D1_Balance Sheet'!B22/'D1_Balance Sheet'!$B$19) -> 0 | C23: =('D1_Balance Sheet'!C22/'D1_Balance Sheet'!$C$19) -> 0 | D23: =('D1_Balance Sheet'!D23/'D1_Balance Sheet'!$D$19) -> 0.1799861 | E23: =('D1_Balance Sheet'!E22/'D1_Balance Sheet'!$E$19) -> 0 | F23: =('D1_Balance Sheet'!F22/'D1_Balance Sheet'!$F$19) -> 0 | G23: =('D1_Balance Sheet'!G22/'D1_Balance Sheet'!$G$19) -> 0
A24: Ford Credit Debt Payable within One Year | B24: =('D1_Balance Sheet'!B23/'D1_Balance Sheet'!$B$19) -> 0.17897358 | C24: =('D1_Balance Sheet'!C23/'D1_Balance Sheet'!$C$19) -> 0.18651384 | D24: =('D1_Balance Sheet'!D23/'D1_Balance Sheet'!$C$19) -> 0.17248489 | E24: =('D1_Balance Sheet'!E23/'D1_Balance Sheet'!$E$19) -> 0.1931891 | F24: =('D1_Balance Sheet'!F23/'D1_Balance Sheet'!$F$19) -> 0.18097535 | G24: =('D1_Balance Sheet'!G23/'D1_Balance Sheet'!$G$19) -> 0.18696705
A25: Payables | B25: =('D1_Balance Sheet'!B24/'D1_Balance Sheet'!$B$19) -> 0.089255084 | C25: =('D1_Balance Sheet'!C24/'D1_Balance Sheet'!$C$19) -> 0.084601467 | D25: =('D1_Balance Sheet'!D24/'D1_Balance Sheet'!$D$19) -> 0.095100801 | E25: =('D1_Balance Sheet'!E24/'D1_Balance Sheet'!$E$19) -> 0.10006487 | F25: =('D1_Balance Sheet'!F24/'D1_Balance Sheet'!$F$19) -> 0.086949248 | G25: =('D1_Balance Sheet'!G24/'D1_Balance Sheet'!$G$19) -> 0.083079836
A26: Other Liabilities and Deferred Revenue | B26: =('D1_Balance Sheet'!B25/'D1_Balance Sheet'!$B$19) -> 0.10990109 | C26: =('D1_Balance Sheet'!C25/'D1_Balance Sheet'!$C$19) -> 0.097413708 | D26: =('D1_Balance Sheet'!D25/'D1_Balance Sheet'!$D$19) -> 0.094654422 | E26: =('D1_Balance Sheet'!E25/'D1_Balance Sheet'!$E$19) -> 0.082447515 | F26: =('D1_Balance Sheet'!F25/'D1_Balance Sheet'!$F$19) -> 0.072698271 | G26: =('D1_Balance Sheet'!G25/'D1_Balance Sheet'!$G$19) -> 0.088471569
A27: Total Current Liabilities | B27: =('D1_Balance Sheet'!B26/'D1_Balance Sheet'!$B$19) -> 0.39732328 | C27: =('D1_Balance Sheet'!C26/'D1_Balance Sheet'!$C$19) -> 0.37468618 | D27: =('D1_Balance Sheet'!D26/'D1_Balance Sheet'!$D$19) -> 0.37148659 | E27: =('D1_Balance Sheet'!E26/'D1_Balance Sheet'!$E$19) -> 0.37855434 | F27: =('D1_Balance Sheet'!F26/'D1_Balance Sheet'!$F$19) -> 0.35297528 | G27: =('D1_Balance Sheet'!G26/'D1_Balance Sheet'!$G$19) -> 0.36365949
A28: Noncurrent Liabilities | B28: =('D1_Balance Sheet'!B27/'D1_Balance Sheet'!$B$19) -> 0 | C28: =('D1_Balance Sheet'!C27/'D1_Balance Sheet'!$C$19) -> 0 | D28: =('D1_Balance Sheet'!D27/'D1_Balance Sheet'!$D$19) -> 0 | E28: =('D1_Balance Sheet'!E27/'D1_Balance Sheet'!$E$19) -> 0 | F28: =('D1_Balance Sheet'!F27/'D1_Balance Sheet'!$F$19) -> 0 | G28: =('D1_Balance Sheet'!G27/'D1_Balance Sheet'!$G$19) -> 0
A29: Company Excluding Ford Credit | B29: =('D1_Balance Sheet'!B28/'D1_Balance Sheet'!$B$19) -> 0.056608798 | C29: =('D1_Balance Sheet'!C28/'D1_Balance Sheet'!$C$19) -> 0.066263201 | D29: =('D1_Balance Sheet'!D28/'D1_Balance Sheet'!$D$19) -> 0.071226812 | E29: =('D1_Balance Sheet'!E28/'D1_Balance Sheet'!$E$19) -> 0.075034 | F29: =('D1_Balance Sheet'!F28/'D1_Balance Sheet'!$F$19) -> 0.066916957 | G29: =('D1_Balance Sheet'!G28/'D1_Balance Sheet'!$G$19) -> 0.084685008
A30: Deferred Income Taxes | B30: =('D1_Balance Sheet'!B29/'D1_Balance Sheet'!$B$19) -> 0.0046825287 | C30: =('D1_Balance Sheet'!C29/'D1_Balance Sheet'!$C$19) -> 0.0037658312 | D30: =('D1_Balance Sheet'!D29/'D1_Balance Sheet'!$D$19) -> 0.0036771432 | E30: =('D1_Balance Sheet'!E29/'D1_Balance Sheet'!$E$19) -> 0.0060535243 | F30: =('D1_Balance Sheet'!F29/'D1_Balance Sheet'!$F$19) -> 0.0061509133 | G30: =('D1_Balance Sheet'!G29/'D1_Balance Sheet'!$G$19) -> 0.0020130135
A31: Minority Interest | B31: =('D1_Balance Sheet'!B30/'D1_Balance Sheet'!$B$19) -> 9.6832204e-05 | C31: =('D1_Balance Sheet'!C30/'D1_Balance Sheet'!$C$19) -> 8.0646292e-05 | D31: =('D1_Balance Sheet'!D30/'D1_Balance Sheet'!$D$19) -> 9.1471223e-05 | E31: =('D1_Balance Sheet'!E30/'D1_Balance Sheet'!$E$19) -> -0.00029310156 | F31: =('D1_Balance Sheet'!F30/'D1_Balance Sheet'!$F$19) -> 0.00040072364 | G31: =('D1_Balance Sheet'!G30/'D1_Balance Sheet'!$G$19) -> 0.00045274095
A32: Ford Credit | B32: =('D1_Balance Sheet'!B31/'D1_Balance Sheet'!$B$19) -> 0 | C32: =('D1_Balance Sheet'!C31/'D1_Balance Sheet'!$C$19) -> 0 | D32: =('D1_Balance Sheet'!D32/'D1_Balance Sheet'!$D$19) -> 0.2930555 | E32: =('D1_Balance Sheet'!E31/'D1_Balance Sheet'!$E$19) -> 0 | F32: =('D1_Balance Sheet'!F31/'D1_Balance Sheet'!$F$19) -> 0 | G32: =('D1_Balance Sheet'!G31/'D1_Balance Sheet'!$G$19) -> 0
A33: Ford Credit Long- Term Debt | B33: =('D1_Balance Sheet'!B32/'D1_Balance Sheet'!$B$19) -> 0.31008784 | C33: =('D1_Balance Sheet'!C32/'D1_Balance Sheet'!$C$19) -> 0.29690108 | D33: =('D1_Balance Sheet'!D32/'D1_Balance Sheet'!$C$19) -> 0.28084195 | E33: =('D1_Balance Sheet'!E32/'D1_Balance Sheet'!$E$19) -> 0.27201779 | F33: =('D1_Balance Sheet'!F32/'D1_Balance Sheet'!$F$19) -> 0.27700508 | G33: =('D1_Balance Sheet'!G32/'D1_Balance Sheet'!$G$19) -> 0.32817358
A34: Other Liabilities and Deferred Revenue | B34: =('D1_Balance Sheet'!B33/'D1_Balance Sheet'!$B$19) -> 0.10686817 | C34: =('D1_Balance Sheet'!C33/'D1_Balance Sheet'!$C$19) -> 0.10109539 | D34: =('D1_Balance Sheet'!D33/'D1_Balance Sheet'!$D$19) -> 0.10396253 | E34: =('D1_Balance Sheet'!E33/'D1_Balance Sheet'!$E$19) -> 0.099642807 | F34: =('D1_Balance Sheet'!F33/'D1_Balance Sheet'!$F$19) -> 0.10778688 | G34: =('D1_Balance Sheet'!G33/'D1_Balance Sheet'!$G$19) -> 0.10618459
A35: Shareholders' Equity | B35: =('D1_Balance Sheet'!B34/'D1_Balance Sheet'!$B$19) -> 0 | C35: =('D1_Balance Sheet'!C34/'D1_Balance Sheet'!$C$19) -> 0 | D35: =('D1_Balance Sheet'!D34/'D1_Balance Sheet'!$D$19) -> 0 | E35: =('D1_Balance Sheet'!E34/'D1_Balance Sheet'!$E$19) -> 0 | F35: =('D1_Balance Sheet'!F34/'D1_Balance Sheet'!$F$19) -> 0 | G35: =('D1_Balance Sheet'!G34/'D1_Balance Sheet'!$G$19) -> 0
A36: Common Stock - Par Value | B36: =('D1_Balance Sheet'!B35/'D1_Balance Sheet'!$B$19) -> 3.458293e-06 | C36: =('D1_Balance Sheet'!C35/'D1_Balance Sheet'!$C$19) -> 3.5063605e-06 | D36: =('D1_Balance Sheet'!D35/'D1_Balance Sheet'!$D$19) -> 3.6588489e-06 | E36: =('D1_Balance Sheet'!E35/'D1_Balance Sheet'!$E$19) -> 3.9080208e-06 | F36: =('D1_Balance Sheet'!F35/'D1_Balance Sheet'!$F$19) -> 3.8905207e-06 | G36: =('D1_Balance Sheet'!G35/'D1_Balance Sheet'!$G$19) -> 3.7416608e-06
A37: Common Stock - Par Value | B37: =('D1_Balance Sheet'!B36/'D1_Balance Sheet'!$B$19) -> 0.00014179001 | C37: =('D1_Balance Sheet'!C36/'D1_Balance Sheet'!$C$19) -> 0.00014376078 | D37: =('D1_Balance Sheet'!D36/'D1_Balance Sheet'!$D$19) -> 0.00015001281 | E37: =('D1_Balance Sheet'!E36/'D1_Balance Sheet'!$E$19) -> 0.00016022885 | F37: =('D1_Balance Sheet'!F36/'D1_Balance Sheet'!$F$19) -> 0.00015562083 | G37: =('D1_Balance Sheet'!G36/'D1_Balance Sheet'!$G$19) -> 0.00014966643
A38: Additional Paid in Capital | B38: =('D1_Balance Sheet'!B37/'D1_Balance Sheet'!$B$19) -> 0.082729285 | C38: =('D1_Balance Sheet'!C37/'D1_Balance Sheet'!$C$19) -> 0.082406485 | D38: =('D1_Balance Sheet'!D37/'D1_Balance Sheet'!$D$19) -> 0.084621858 | E38: =('D1_Balance Sheet'!E37/'D1_Balance Sheet'!$E$19) -> 0.089227931 | F38: =('D1_Balance Sheet'!F37/'D1_Balance Sheet'!$F$19) -> 0.087968565 | G38: =('D1_Balance Sheet'!G37/'D1_Balance Sheet'!$G$19) -> 0.083401619
A39: Treasury Stock - Common | B39: =('D1_Balance Sheet'!B38/'D1_Balance Sheet'!$B$19) -> -0.0097178033 | C39: =('D1_Balance Sheet'!C38/'D1_Balance Sheet'!$C$19) -> -0.0098528731 | D39: =('D1_Balance Sheet'!D38/'D1_Balance Sheet'!$D$19) -> -0.0087226958 | E39: =('D1_Balance Sheet'!E38/'D1_Balance Sheet'!$E$19) -> -0.0079997186 | F39: =('D1_Balance Sheet'!F38/'D1_Balance Sheet'!$F$19) -> -0.0060808839 | G39: =('D1_Balance Sheet'!G38/'D1_Balance Sheet'!$G$19) -> -0.0059492406
A40: Retained Earnings | B40: =('D1_Balance Sheet'!B39/'D1_Balance Sheet'!$B$19) -> 0 | C40: =('D1_Balance Sheet'!C39/'D1_Balance Sheet'!$C$19) -> 0 | D40: =('D1_Balance Sheet'!D40/'D1_Balance Sheet'!$D$19) -> 0.11353042 | E40: =('D1_Balance Sheet'!E39/'D1_Balance Sheet'!$E$19) -> 0 | F40: =('D1_Balance Sheet'!F39/'D1_Balance Sheet'!$F$19) -> 0 | G40: =('D1_Balance Sheet'!G39/'D1_Balance Sheet'!$G$19) -> 0
A41: Retained Earnings (Accumulated Deficit) | B41: =('D1_Balance Sheet'!B40/'D1_Balance Sheet'!$B$19) -> 0.077839259 | C41: =('D1_Balance Sheet'!C40/'D1_Balance Sheet'!$C$19) -> 0.1183046 | D41: =('D1_Balance Sheet'!D40/'D1_Balance Sheet'!$C$19) -> 0.10879886 | E41: =('D1_Balance Sheet'!E40/'D1_Balance Sheet'!$E$19) -> 0.12409529 | F41: =('D1_Balance Sheet'!F40/'D1_Balance Sheet'!$F$19) -> 0.13916004 | G41: =('D1_Balance Sheet'!G40/'D1_Balance Sheet'!$G$19) -> 0.068259117
A42: Accumulated Other Comprehensive Income (Loss) | B42: =('D1_Balance Sheet'!B41/'D1_Balance Sheet'!$B$19) -> -0.026663439 | C42: =('D1_Balance Sheet'!C41/'D1_Balance Sheet'!$C$19) -> -0.033797809 | D42: =('D1_Balance Sheet'!D41/'D1_Balance Sheet'!$D$19) -> -0.033083312 | E42: =('D1_Balance Sheet'!E41/'D1_Balance Sheet'!$E$19) -> -0.036497006 | F42: =('D1_Balance Sheet'!F41/'D1_Balance Sheet'!$F$19) -> -0.032443053 | G42: =('D1_Balance Sheet'!G41/'D1_Balance Sheet'!$G$19) -> -0.031033334
A43: Total Shareholders Equity | B43: =('D1_Balance Sheet'!B42/'D1_Balance Sheet'!$B$19) -> 0.12433255 | C43: =('D1_Balance Sheet'!C42/'D1_Balance Sheet'!$C$19) -> 0.15720767 | D43: =('D1_Balance Sheet'!D42/'D1_Balance Sheet'!$D$19) -> 0.15649995 | E43: =('D1_Balance Sheet'!E42/'D1_Balance Sheet'!$E$19) -> 0.16899064 | F43: =('D1_Balance Sheet'!F42/'D1_Balance Sheet'!$F$19) -> 0.18876418 | G43: =('D1_Balance Sheet'!G42/'D1_Balance Sheet'!$G$19) -> 0.11483157
A44: Total Liabilities & Shareholders Equity | B44: =('D1_Balance Sheet'!B43/'D1_Balance Sheet'!$B$19) -> 1 | C44: =('D1_Balance Sheet'!C43/'D1_Balance Sheet'!$C$19) -> 1 | D44: =('D1_Balance Sheet'!D43/'D1_Balance Sheet'!$D$19) -> 1 | E44: =('D1_Balance Sheet'!E43/'D1_Balance Sheet'!$E$19) -> 1 | F44: =('D1_Balance Sheet'!F43/'D1_Balance Sheet'!$F$19) -> 1 | G44: =('D1_Balance Sheet'!G43/'D1_Balance Sheet'!$G$19) -> 1
A46: Long Term Liabilities | B46: =1-B27-B43 -> 0.47834417 | C46: =1-C27-C43 -> 0.46810614 | D46: =1-D27-D43 -> 0.47201346 | E46: =1-E27-E43 -> 0.45245502 | F46: =1-F27-F43 -> 0.45826055 | G46: =1-G27-G43 -> 0.52150894

Sheet D2_Fig_BSCommonGraph

Sheet D2_Liquidity-NWCandNOWC
B1: Year(t=0) | C1: Year(t=-1) | D1: Year(t=-2) | E1: Year(t=-3) | F1: Year(t=-4) | G1: Year(t=-5)
B2: 2025 | C2: 2024 | D2: 2023 | E2: 2022 | F2: 2021 | G2: 2020
A3: Net Working Capital = CA-CL | B3: ='D1_Balance Sheet'!B11-'D1_Balance Sheet'!B26 -> 8597 | C3: ='D1_Balance Sheet'!C11-'D1_Balance Sheet'!C26 -> 17615 | D3: ='D1_Balance Sheet'!D11-'D1_Balance Sheet'!D26 -> 19950 | E3: ='D1_Balance Sheet'!E11-'D1_Balance Sheet'!E26 -> 19610 | F3: ='D1_Balance Sheet'!F11-'D1_Balance Sheet'!F26 -> 18269 | G3: ='D1_Balance Sheet'!G11-'D1_Balance Sheet'!G26 -> 19552
A5: (Notes payable(NP)) | B5: ='D1_Balance Sheet'!B21+'D1_Balance Sheet'!B22+'D1_Balance Sheet'!B23 -> 57302 | C5: ='D1_Balance Sheet'!C21+'D1_Balance Sheet'!C22+'D1_Balance Sheet'!C23 -> 54949 | D5: ='D1_Balance Sheet'!D21+'D1_Balance Sheet'!D22+'D1_Balance Sheet'!D23 -> 49669 | E5: ='D1_Balance Sheet'!E21+'D1_Balance Sheet'!E22+'D1_Balance Sheet'!E23 -> 50164 | F5: ='D1_Balance Sheet'!F21+'D1_Balance Sheet'!F22+'D1_Balance Sheet'!F23 -> 49692 | G5: ='D1_Balance Sheet'!G21+'D1_Balance Sheet'!G22+'D1_Balance Sheet'!G23 -> 51343
A7: Net Operating Working Capital = CA-(CL-NP) | B7: ='D1_Balance Sheet'!B11-('D1_Balance Sheet'!B26-B5) -> 65899 | C7: ='D1_Balance Sheet'!C11-('D1_Balance Sheet'!C26-C5) -> 72564 | D7: ='D1_Balance Sheet'!D11-('D1_Balance Sheet'!D26-D5) -> 69619 | E7: ='D1_Balance Sheet'!E11-('D1_Balance Sheet'!E26-E5) -> 69774 | F7: ='D1_Balance Sheet'!F11-('D1_Balance Sheet'!F26-F5) -> 67961 | G7: ='D1_Balance Sheet'!G11-('D1_Balance Sheet'!G26-G5) -> 70895
A9: Change in Working Capital (current year - previous year) | B9: =B7-C7 -> -6665 | C9: =C7-D7 -> 2945 | D9: =D7-E7 -> -155 | E9: =E7-F7 -> 1813 | F9: =F7-G7 -> -2934
A11: Free Cash Flow = (EBIT(1-T)+Dep)-(Capex + Change in NOWC) | B11: =(D1_IncomeStatment!B28*(1-0.21)+D1_StatmentofCFs!B5)-('D2_Liquidity-NWCandNOWC'!B13+'D2_Liquidity-NWCandNOWC'!B9) -> 4061.49 | C11: =(D1_IncomeStatment!C28*(1-0.21)+D1_StatmentofCFs!C5)-('D2_Liquidity-NWCandNOWC'!C13+'D2_Liquidity-NWCandNOWC'!C9) -> 71.01 | D11: =(D1_IncomeStatment!D28*(1-0.21)+D1_StatmentofCFs!D5)-('D2_Liquidity-NWCandNOWC'!D13+'D2_Liquidity-NWCandNOWC'!D9) -> 910.82 | E11: =(D1_IncomeStatment!E28*(1-0.21)+D1_StatmentofCFs!E5)-('D2_Liquidity-NWCandNOWC'!E13+'D2_Liquidity-NWCandNOWC'!E9) -> 3019.04 | F11: =(D1_IncomeStatment!F28*(1-0.21)+D1_StatmentofCFs!F5)-('D2_Liquidity-NWCandNOWC'!F13+'D2_Liquidity-NWCandNOWC'!F9) -> 6451.17
A13: Capex = NFA1- NFA0 +DEP | B13: ='D1_Balance Sheet'!B13-'D1_Balance Sheet'!C13+D1_StatmentofCFs!B5 -> 3194 | C13: ='D1_Balance Sheet'!C13-'D1_Balance Sheet'!D13+D1_StatmentofCFs!C5 -> 8674 | D13: ='D1_Balance Sheet'!D13-'D1_Balance Sheet'!E13+D1_StatmentofCFs!D5 -> 11246 | E13: ='D1_Balance Sheet'!E13-'D1_Balance Sheet'!F13+D1_StatmentofCFs!E5 -> 7768 | F13: ='D1_Balance Sheet'!F13-'D1_Balance Sheet'!G13+D1_StatmentofCFs!F5 -> 7374
B20: Year(t=0) | C20: Year(t=-1) | D20: Year(t=-2) | E20: Year(t=-3) | F20: Year(t=-4) | G20: Year(t=-5)
B21: 2025 | C21: 2024 | D21: 2023 | E21: 2022 | F21: 2021 | G21: 2020
A22: Net Working Capital = CA-CL | B22: =('D1_Balance Sheet'!B11-'D1_Balance Sheet'!B8)-('D1_Balance Sheet'!B26-'D1_Balance Sheet'!B23) -> 11219 | C22: =('D1_Balance Sheet'!C11-'D1_Balance Sheet'!C8)-('D1_Balance Sheet'!C26-'D1_Balance Sheet'!C23) -> 18958 | D22: =('D1_Balance Sheet'!D11-'D1_Balance Sheet'!D8)-('D1_Balance Sheet'!D26-'D1_Balance Sheet'!D23) -> 22717 | E22: =('D1_Balance Sheet'!E11-'D1_Balance Sheet'!E8)-('D1_Balance Sheet'!E26-'D1_Balance Sheet'!E23) -> 30324 | F22: =('D1_Balance Sheet'!F11-'D1_Balance Sheet'!F8)-('D1_Balance Sheet'!F26-'D1_Balance Sheet'!F23) -> 32243 | G22: =('D1_Balance Sheet'!G11-'D1_Balance Sheet'!G8)-('D1_Balance Sheet'!G26-'D1_Balance Sheet'!G23) -> 27120
A23: (Total current assests- Minus Ford Credit) - (Total current liabilities Minus Ford Credit Debt)
A26: Net Operating Working Capital = CA-(CL-NP) | B26: =('D1_Balance Sheet'!B11-'D1_Balance Sheet'!B8)-(('D1_Balance Sheet'!B26-'D1_Balance Sheet'!B23)-'D1_Balance Sheet'!B21) -> 16769 | C26: =('D1_Balance Sheet'!C11-'D1_Balance Sheet'!C8)-(('D1_Balance Sheet'!C26-'D1_Balance Sheet'!C23)-'D1_Balance Sheet'!C21) -> 20714 | D26: =('D1_Balance Sheet'!D11-'D1_Balance Sheet'!D8)-(('D1_Balance Sheet'!D26-'D1_Balance Sheet'!D23)-'D1_Balance Sheet'!D21) -> 23194 | E26: =('D1_Balance Sheet'!E11-'D1_Balance Sheet'!E8)-(('D1_Balance Sheet'!E26-'D1_Balance Sheet'!E23)-'D1_Balance Sheet'!E21) -> 31054 | F26: =('D1_Balance Sheet'!F11-'D1_Balance Sheet'!F8)-(('D1_Balance Sheet'!F26-'D1_Balance Sheet'!F23)-'D1_Balance Sheet'!F21) -> 35418 | G26: =('D1_Balance Sheet'!G11-'D1_Balance Sheet'!G8)-(('D1_Balance Sheet'!G26-'D1_Balance Sheet'!G23)-'D1_Balance Sheet'!G21) -> 28494
A28: Change in Working Capital (current year - previous year) | B28: =B26-C26 -> -3945 | C28: =C26-D26 -> -2480 | D28: =D26-E26 -> -7860 | E28: =E26-F26 -> -4364 | F28: =F26-G26 -> 6924 | G28: =G26-H26 -> 28494
A30: Free Cash Flow = (EBIT(1-T)+Dep)-(Capex + Change in NOWC) | B30: =(D1_IncomeStatment!B28*(1-0.21)+D1_StatmentofCFs!B5)-('D2_Liquidity-NWCandNOWC'!B32+'D2_Liquidity-NWCandNOWC'!B28) -> 1341.49 | C30: =(D1_IncomeStatment!C28*(1-0.21)+D1_StatmentofCFs!C5)-('D2_Liquidity-NWCandNOWC'!C32+'D2_Liquidity-NWCandNOWC'!C28) -> 5496.01 | D30: =(D1_IncomeStatment!D28*(1-0.21)+D1_StatmentofCFs!D5)-('D2_Liquidity-NWCandNOWC'!D32+'D2_Liquidity-NWCandNOWC'!D28) -> 8615.82 | E30: =(D1_IncomeStatment!E28*(1-0.21)+D1_StatmentofCFs!E5)-('D2_Liquidity-NWCandNOWC'!E32+'D2_Liquidity-NWCandNOWC'!E28) -> 9196.04 | F30: =(D1_IncomeStatment!F28*(1-0.21)+D1_StatmentofCFs!F5)-('D2_Liquidity-NWCandNOWC'!F32+'D2_Liquidity-NWCandNOWC'!F28) -> -3406.83
A32: Capex = NFA1- NFA0 +DEP | B32: ='D1_Balance Sheet'!B13-'D1_Balance Sheet'!C13+D1_StatmentofCFs!B5 -> 3194 | C32: ='D1_Balance Sheet'!C13-'D1_Balance Sheet'!D13+D1_StatmentofCFs!C5 -> 8674 | D32: ='D1_Balance Sheet'!D13-'D1_Balance Sheet'!E13+D1_StatmentofCFs!D5 -> 11246 | E32: ='D1_Balance Sheet'!E13-'D1_Balance Sheet'!F13+D1_StatmentofCFs!E5 -> 7768 | F32: ='D1_Balance Sheet'!F13-'D1_Balance Sheet'!G13+D1_StatmentofCFs!F5 -> 7374

Sheet D3_BalSheetHorizontalAnalysis
A1: Line Items | B1: 2025 | C1: 2024 | D1: 2023 | E1: 2022 | F1: 2021 | G1: 2020 | M1: Year | N1: 2020 | O1: 2021 | P1: 2022 | Q1: 2023 | R1: 2024 | S1: 2025
M2: Cash and Cash Equivalents | N2: 25243 | O2: 20540 | P2: 25134 | Q2: 24862 | R2: 22935 | S2: 23356
A3: Current Assets | G3: - | M3: % change | N3: - | O3: =F4 -> -0.18630908 | P3: =E4 -> 0.22366115 | Q3: =D4 -> -0.010821994 | R3: =C4 -> -0.077507843 | S3: =B4 -> 0.018356224
A4: Cash and Cash Equivalents | B4: =('D1_Balance Sheet'!$B$4-'D1_Balance Sheet'!$C$4)/ABS('D1_Balance Sheet'!$C$4) -> 0.018356224 | C4: =('D1_Balance Sheet'!$C$4-'D1_Balance Sheet'!$D$4)/ABS('D1_Balance Sheet'!$D$4) -> -0.077507843 | D4: =('D1_Balance Sheet'!D4-'D1_Balance Sheet'!E4)/ABS('D1_Balance Sheet'!E4) -> -0.010821994 | E4: =('D1_Balance Sheet'!E4-'D1_Balance Sheet'!F4)/ABS('D1_Balance Sheet'!F4) -> 0.22366115 | F4: =('D1_Balance Sheet'!F4-'D1_Balance Sheet'!G4)/ABS('D1_Balance Sheet'!G4) -> -0.18630908 | G4: -
A5: Trade and Other Receivables | B5: =('D1_Balance Sheet'!B6-'D1_Balance Sheet'!C6)/ABS('D1_Balance Sheet'!C6) -> 0.045846635 | C5: =('D1_Balance Sheet'!C6-'D1_Balance Sheet'!D6)/ABS('D1_Balance Sheet'!D6) -> -0.056278444 | D5: =('D1_Balance Sheet'!D6-'D1_Balance Sheet'!E6)/ABS('D1_Balance Sheet'!E6) -> -0.0081378346 | E5: =('D1_Balance Sheet'!E6-'D1_Balance Sheet'!F6)/ABS('D1_Balance Sheet'!F6) -> 0.38337731 | F5: =('D1_Balance Sheet'!F6-'D1_Balance Sheet'!G6)/ABS('D1_Balance Sheet'!G6) -> 0.13779646 | G5: - | M5: Year | N5: 2020 | O5: 2021 | P5: 2022 | Q5: 2023 | R5: 2024 | S5: 2025
A6: Inventories | B6: =('D1_Balance Sheet'!B7-'D1_Balance Sheet'!C7)/ABS('D1_Balance Sheet'!C7) -> 0.022339643 | C6: =('D1_Balance Sheet'!C7-'D1_Balance Sheet'!D7)/ABS('D1_Balance Sheet'!D7) -> -0.044725577 | D6: =('D1_Balance Sheet'!D7-'D1_Balance Sheet'!E7)/ABS('D1_Balance Sheet'!E7) -> 0.1115767 | E6: =('D1_Balance Sheet'!E7-'D1_Balance Sheet'!F7)/ABS('D1_Balance Sheet'!F7) -> 0.16701202 | F6: =('D1_Balance Sheet'!F7-'D1_Balance Sheet'!G7)/ABS('D1_Balance Sheet'!G7) -> 0.11630274 | G6: - | M6: Total Equity | N6: 30690 | O6: 48519 | P6: 43242 | Q6: 42773 | R6: 44835 | S6: 35952
A7: Noncurrent Assets | G7: - | M7: % Change | N7: - | O7: =F18 -> 0.58093842 | P7: =E18 -> -0.10876152 | Q7: =D18 -> -0.010845937 | R7: =C18 -> 0.048207982 | S7: =B18 -> -0.19812646
A8: Property-net | B8: =('D1_Balance Sheet'!B13-'D1_Balance Sheet'!C13)/ABS('D1_Balance Sheet'!C13) -> -0.1106659 | C8: =('D1_Balance Sheet'!C13-'D1_Balance Sheet'!D13)/ABS('D1_Balance Sheet'!D13) -> 0.027118395 | D8: =('D1_Balance Sheet'!D13-'D1_Balance Sheet'!E13)/ABS('D1_Balance Sheet'!E13) -> 0.095424661 | E8: =('D1_Balance Sheet'!E13-'D1_Balance Sheet'!F13)/ABS('D1_Balance Sheet'!F13) -> 0.00339266 | F8: =('D1_Balance Sheet'!F13-'D1_Balance Sheet'!G13)/ABS('D1_Balance Sheet'!G13) -> 0.0015101259 | G8: -
A9: Total Assets | B9: =('D1_Balance Sheet'!B19-'D1_Balance Sheet'!C19)/ABS('D1_Balance Sheet'!C19) -> 0.013899213 | C9: =('D1_Balance Sheet'!C19-'D1_Balance Sheet'!D19)/ABS('D1_Balance Sheet'!D19) -> 0.043489078 | D9: =('D1_Balance Sheet'!D19-'D1_Balance Sheet'!E19)/ABS('D1_Balance Sheet'!E19) -> 0.068101171 | E9: =('D1_Balance Sheet'!E19-'D1_Balance Sheet'!F19)/ABS('D1_Balance Sheet'!F19) -> -0.0044779894 | F9: =('D1_Balance Sheet'!F19-'D1_Balance Sheet'!G19)/ABS('D1_Balance Sheet'!G19) -> -0.038262223 | G9: - | M9: Year | N9: 2020 | O9: 2021 | P9: 2022 | Q9: 2023 | R9: 2024 | S9: 2025
A10: Current Liabilities | G10: - | M10: Long-Term Debt | N10: 87708 | O10: 71200 | P10: 69605 | Q10: 80095 | R10: 84675 | S10: 89665
A11: Payables | B11: =('D1_Balance Sheet'!B24-'D1_Balance Sheet'!C24)/ABS('D1_Balance Sheet'!C24) -> 0.069670093 | C11: =('D1_Balance Sheet'!C24-'D1_Balance Sheet'!D24)/ABS('D1_Balance Sheet'!D24) -> -0.071714374 | D11: =('D1_Balance Sheet'!D24-'D1_Balance Sheet'!E24)/ABS('D1_Balance Sheet'!E24) -> 0.015114236 | E11: =('D1_Balance Sheet'!E24-'D1_Balance Sheet'!F24)/ABS('D1_Balance Sheet'!F24) -> 0.14568885 | F11: =('D1_Balance Sheet'!F24-'D1_Balance Sheet'!G24)/ABS('D1_Balance Sheet'!G24) -> 0.0065303549 | G11: - | M11: % Change | N11: - | O11: =F13 -> -0.18821544 | P11: =E13 -> -0.022401685 | Q11: =D13 -> 0.15070756 | R11: =C13 -> 0.057182096 | S11: =B13 -> 0.058931208
A12: Ford Credit Debt Payable within One Year | B12: =('D1_Balance Sheet'!B23-'D1_Balance Sheet'!C23)/ABS('D1_Balance Sheet'!C23) -> -0.027090031 | C12: =('D1_Balance Sheet'!C23-'D1_Balance Sheet'!D23)/ABS('D1_Balance Sheet'!D23) -> 0.081334363 | D12: =('D1_Balance Sheet'!D23-'D1_Balance Sheet'!E23)/ABS('D1_Balance Sheet'!E23) -> -0.0048954161 | E12: =('D1_Balance Sheet'!E23-'D1_Balance Sheet'!F23)/ABS('D1_Balance Sheet'!F23) -> 0.062708257 | F12: =('D1_Balance Sheet'!F23-'D1_Balance Sheet'!G23)/ABS('D1_Balance Sheet'!G23) -> -0.069082831 | G12: -
A13: Ford Credit Long- Term Debt | B13: =('D1_Balance Sheet'!B32-'D1_Balance Sheet'!C32)/ABS('D1_Balance Sheet'!C32) -> 0.058931208 | C13: =('D1_Balance Sheet'!C32-'D1_Balance Sheet'!D32)/ABS('D1_Balance Sheet'!D32) -> 0.057182096 | D13: =('D1_Balance Sheet'!D32-'D1_Balance Sheet'!E32)/ABS('D1_Balance Sheet'!E32) -> 0.15070756 | E13: =('D1_Balance Sheet'!E32-'D1_Balance Sheet'!F32)/ABS('D1_Balance Sheet'!F32) -> -0.022401685 | F13: =('D1_Balance Sheet'!F32-'D1_Balance Sheet'!G32)/ABS('D1_Balance Sheet'!G32) -> -0.18821544 | G13: - | M13: Year | N13: 2020 | O13: 2021 | P13: 2022 | Q13: 2023 | R13: 2024 | S13: 2025
A14: Total Liabilities | B14: =(('D1_Balance Sheet'!B43-'D1_Balance Sheet'!B42)-('D1_Balance Sheet'!C43-'D1_Balance Sheet'!C42))/ABS('D1_Balance Sheet'!C43-'D1_Balance Sheet'!C42) -> 0.053448771 | C14: =(('D1_Balance Sheet'!C43-'D1_Balance Sheet'!C42)-('D1_Balance Sheet'!D43-'D1_Balance Sheet'!D42))/ABS('D1_Balance Sheet'!D43-'D1_Balance Sheet'!D42) -> 0.04261355 | D14: =(('D1_Balance Sheet'!D43-'D1_Balance Sheet'!D42)-('D1_Balance Sheet'!E43-'D1_Balance Sheet'!E42))/ABS('D1_Balance Sheet'!E43-'D1_Balance Sheet'!E42) -> 0.084155529 | E14: =(('D1_Balance Sheet'!E43-'D1_Balance Sheet'!E42)-('D1_Balance Sheet'!F43-'D1_Balance Sheet'!F42))/ABS('D1_Balance Sheet'!F43-'D1_Balance Sheet'!F42) -> 0.01978745 | F14: =(('D1_Balance Sheet'!F43-'D1_Balance Sheet'!F42)-('D1_Balance Sheet'!G43-'D1_Balance Sheet'!G42))/ABS('D1_Balance Sheet'!G43-'D1_Balance Sheet'!G42) -> -0.11859019 | G14: - | M14: Trade and Other Receivables | N14: 9993 | O14: 11370 | P14: 15729 | Q14: 15601 | R14: 14723 | S14: 15398
A15: Shareholders' Equity | G15: - | M15: % Change | N15: - | O15: =F5 -> 0.13779646 | P15: =E5 -> 0.38337731 | Q15: =D5 -> -0.0081378346 | R15: =C5 -> -0.056278444 | S15: =B5 -> 0.045846635
A16: Common Stock - Par Value | B16: =('D1_Balance Sheet'!B36-'D1_Balance Sheet'!C36)/ABS('D1_Balance Sheet'!C36) -> 0 | C16: =('D1_Balance Sheet'!C36-'D1_Balance Sheet'!D36)/ABS('D1_Balance Sheet'!D36) -> 0 | D16: =('D1_Balance Sheet'!D36-'D1_Balance Sheet'!E36)/ABS('D1_Balance Sheet'!E36) -> 0 | E16: =('D1_Balance Sheet'!E36-'D1_Balance Sheet'!F36)/ABS('D1_Balance Sheet'!F36) -> 0.025 | F16: =('D1_Balance Sheet'!F36-'D1_Balance Sheet'!G36)/ABS('D1_Balance Sheet'!G36) -> 0 | G16: -
A17: Retained Earnings (Accumulated Deficit) | B17: =('D1_Balance Sheet'!B40-'D1_Balance Sheet'!C40)/ABS('D1_Balance Sheet'!C40) -> -0.33289864 | C17: =('D1_Balance Sheet'!C40-'D1_Balance Sheet'!D40)/ABS('D1_Balance Sheet'!D40) -> 0.08736988 | D17: =('D1_Balance Sheet'!D40-'D1_Balance Sheet'!E40)/ABS('D1_Balance Sheet'!E40) -> -0.022831769 | E17: =('D1_Balance Sheet'!E40-'D1_Balance Sheet'!F40)/ABS('D1_Balance Sheet'!F40) -> -0.11224804 | F17: =('D1_Balance Sheet'!F40-'D1_Balance Sheet'!G40)/ABS('D1_Balance Sheet'!G40) -> 0.96069725 | G17: - | M17: Year | N17: 2020 | O17: 2021 | P17: 2022 | Q17: 2023 | R17: 2024 | S17: 2025
A18: Total Equity | B18: =('D1_Balance Sheet'!B42-'D1_Balance Sheet'!C42)/ABS('D1_Balance Sheet'!C42) -> -0.19812646 | C18: =('D1_Balance Sheet'!C42-'D1_Balance Sheet'!D42)/ABS('D1_Balance Sheet'!D42) -> 0.048207982 | D18: =('D1_Balance Sheet'!D42-'D1_Balance Sheet'!E42)/ABS('D1_Balance Sheet'!E42) -> -0.010845937 | E18: =('D1_Balance Sheet'!E42-'D1_Balance Sheet'!F42)/ABS('D1_Balance Sheet'!F42) -> -0.10876152 | F18: =('D1_Balance Sheet'!F42-'D1_Balance Sheet'!G42)/ABS('D1_Balance Sheet'!G42) -> 0.58093842 | G18: - | M18: Trade and Other Receivables | N18: ='D1_Balance Sheet'!G6 -> 9993 | O18: ='D1_Balance Sheet'!F6 -> 11370 | P18: ='D1_Balance Sheet'!E6 -> 15729 | Q18: ='D1_Balance Sheet'!D6 -> 15601 | R18: ='D1_Balance Sheet'!C6 -> 14723 | S18: ='D1_Balance Sheet'!B6 -> 15398
A19: Additional Paid in Capital | B19: =('D1_Balance Sheet'!B37-'D1_Balance Sheet'!C37)/ABS('D1_Balance Sheet'!C37) -> 0.01787082 | C19: =('D1_Balance Sheet'!C37-'D1_Balance Sheet'!D37)/ABS('D1_Balance Sheet'!D37) -> 0.016170875 | D19: =('D1_Balance Sheet'!D37-'D1_Balance Sheet'!E37)/ABS('D1_Balance Sheet'!E37) -> 0.012964261 | E19: =('D1_Balance Sheet'!E37-'D1_Balance Sheet'!F37)/ABS('D1_Balance Sheet'!F37) -> 0.0097740038 | F19: =('D1_Balance Sheet'!F37-'D1_Balance Sheet'!G37)/ABS('D1_Balance Sheet'!G37) -> 0.014401077 | G19: - | M19: % Change AR | N19: 0 | O19: =F5 -> 0.13779646 | P19: =E5 -> 0.38337731 | Q19: =D5 -> -0.0081378346 | R19: =C5 -> -0.056278444 | S19: =B5 -> 0.045846635
A20: Accumulated Other Comprehensive Income (Loss) | B20: =('D1_Balance Sheet'!B41-'D1_Balance Sheet'!C41)/ABS('D1_Balance Sheet'!C41) -> 0.20012449 | C20: =('D1_Balance Sheet'!C41-'D1_Balance Sheet'!D41)/ABS('D1_Balance Sheet'!D41) -> -0.066025216 | D20: =('D1_Balance Sheet'!D41-'D1_Balance Sheet'!E41)/ABS('D1_Balance Sheet'!E41) -> 0.03180212 | E20: =('D1_Balance Sheet'!E41-'D1_Balance Sheet'!F41)/ABS('D1_Balance Sheet'!F41) -> -0.11991846 | F20: =('D1_Balance Sheet'!F41-'D1_Balance Sheet'!G41)/ABS('D1_Balance Sheet'!G41) -> -0.0054256089 | G20: - | M20: Revenue | N20: =D1_IncomeStatment!G9 -> 127144 | O20: =D1_IncomeStatment!F9 -> 136341 | P20: =D1_IncomeStatment!E9 -> 158057 | Q20: =D1_IncomeStatment!D9 -> 176191 | R20: =D1_IncomeStatment!C9 -> 184992 | S20: =D1_IncomeStatment!B9 -> 187267
M21: % Change Rev | N21: 0 | O21: =D3_ISHorizontalAnalysis!F3 -> 0.072335305 | P21: =D3_ISHorizontalAnalysis!E3 -> 0.15927711 | Q21: =D3_ISHorizontalAnalysis!D3 -> 0.11473076 | R21: =D3_ISHorizontalAnalysis!C3 -> 0.049951473 | S21: =D3_ISHorizontalAnalysis!B3 -> 0.012297829

Sheet D3_Analysis of Balance Sheet
A1: *Please use calculations as shown in the slides and/or textbook (please do not use the internet)
B2: Year(t=0) | C2: Year(t=-1) | D2: Year(t=-2) | E2: Year(t=-3) | F2: Year(t=-4) | G2: Year(t=-5)
A3: Liquidity Ratios
A4: Current Ratio | B4: ='D1_Balance Sheet'!B11/'D1_Balance Sheet'!B26 -> 1.0748281 | C4: ='D1_Balance Sheet'!C11/'D1_Balance Sheet'!C26 -> 1.1648434 | D4: ='D1_Balance Sheet'!D11/'D1_Balance Sheet'!D26 -> 1.1964917 | E4: ='D1_Balance Sheet'!E11/'D1_Balance Sheet'!E26 -> 1.2024446 | F4: ='D1_Balance Sheet'!F11/'D1_Balance Sheet'!F26 -> 1.2013623 | G4: ='D1_Balance Sheet'!G11/'D1_Balance Sheet'!G26 -> 1.2011688
A5: Quick Ratio | B5: =('D1_Balance Sheet'!B4+'D1_Balance Sheet'!B5+'D1_Balance Sheet'!B6)/'D1_Balance Sheet'!B26 -> 0.46901384 | C5: =('D1_Balance Sheet'!C4+'D1_Balance Sheet'!C5+'D1_Balance Sheet'!C6)/'D1_Balance Sheet'!C26 -> 0.49664511 | D5: =('D1_Balance Sheet'!D4+'D1_Balance Sheet'!D5+'D1_Balance Sheet'!D6)/'D1_Balance Sheet'!D26 -> 0.54931006 | E5: =('D1_Balance Sheet'!E4+'D1_Balance Sheet'!E5+'D1_Balance Sheet'!E6)/'D1_Balance Sheet'!E26 -> 0.61733735 | F5: =('D1_Balance Sheet'!F4+'D1_Balance Sheet'!F5+'D1_Balance Sheet'!F6)/'D1_Balance Sheet'!F26 -> 0.67193889 | G5: =('D1_Balance Sheet'!G4+'D1_Balance Sheet'!G5+'D1_Balance Sheet'!G6)/'D1_Balance Sheet'!G26 -> 0.61686147
A6: Cash Ratio | B6: =('D1_Balance Sheet'!B4+'D1_Balance Sheet'!B6)/'D1_Balance Sheet'!B26 -> 0.33731395 | C6: =('D1_Balance Sheet'!C4+'D1_Balance Sheet'!C6)/'D1_Balance Sheet'!C26 -> 0.35240831 | D6: =('D1_Balance Sheet'!D4+'D1_Balance Sheet'!D6)/'D1_Balance Sheet'!D26 -> 0.39852853 | E6: =('D1_Balance Sheet'!E4+'D1_Balance Sheet'!E6)/'D1_Balance Sheet'!E26 -> 0.4218508 | F6: =('D1_Balance Sheet'!F4+'D1_Balance Sheet'!F6)/'D1_Balance Sheet'!F26 -> 0.35171448 | G6: =('D1_Balance Sheet'!G4+'D1_Balance Sheet'!G6)/'D1_Balance Sheet'!G26 -> 0.36254013
B9: Year(t=0) | C9: Year(t=-1) | D9: Year(t=-2) | E9: Year(t=-3) | F9: Year(t=-4) | G9: Year(t=-5)
A10: Solvency Ratios
A11: Long-term Debt to Equity | B11: ='D1_Balance Sheet'!B32/'D1_Balance Sheet'!B42 -> 2.4940198 | C11: ='D1_Balance Sheet'!C32/'D1_Balance Sheet'!C42 -> 1.8885915 | D11: ='D1_Balance Sheet'!D32/'D1_Balance Sheet'!D42 -> 1.8725598 | E11: ='D1_Balance Sheet'!E32/'D1_Balance Sheet'!E42 -> 1.6096619 | F11: ='D1_Balance Sheet'!F32/'D1_Balance Sheet'!F42 -> 1.4674664 | G11: ='D1_Balance Sheet'!G32/'D1_Balance Sheet'!G42 -> 2.857869
A12: Debt to Equity | B12: ='D1_Balance Sheet'!B26/'D1_Balance Sheet'!B42 -> 3.1956498 | C12: ='D1_Balance Sheet'!C26/'D1_Balance Sheet'!C42 -> 2.3833835 | D12: ='D1_Balance Sheet'!D26/'D1_Balance Sheet'!D42 -> 2.3737171 | E12: ='D1_Balance Sheet'!E26/'D1_Balance Sheet'!E42 -> 2.2400907 | F12: ='D1_Balance Sheet'!F26/'D1_Balance Sheet'!F42 -> 1.8699272 | G12: ='D1_Balance Sheet'!G26/'D1_Balance Sheet'!G42 -> 3.1668948
A13: Debt to Assets | B13: ='D1_Balance Sheet'!B26/'D1_Balance Sheet'!B19 -> 0.39732328 | C13: ='D1_Balance Sheet'!C26/'D1_Balance Sheet'!C19 -> 0.37468618 | D13: ='D1_Balance Sheet'!D26/'D1_Balance Sheet'!D19 -> 0.37148659 | E13: ='D1_Balance Sheet'!E26/'D1_Balance Sheet'!E19 -> 0.37855434 | F13: ='D1_Balance Sheet'!F26/'D1_Balance Sheet'!F19 -> 0.35297528 | G13: ='D1_Balance Sheet'!G26/'D1_Balance Sheet'!G19 -> 0.36365949
A14: Debt to Capital | B14: =('D1_Balance Sheet'!B26+'D1_Balance Sheet'!B32+'D1_Balance Sheet'!B33)/('D1_Balance Sheet'!B26+'D1_Balance Sheet'!B32++'D1_Balance Sheet'!B33+'D1_Balance Sheet'!B42) -> 0.86753571 | C14: =('D1_Balance Sheet'!C26+'D1_Balance Sheet'!C32+'D1_Balance Sheet'!C33)/('D1_Balance Sheet'!C26+'D1_Balance Sheet'!C32++'D1_Balance Sheet'!C33+'D1_Balance Sheet'!C42) -> 0.83093955 | D14: =('D1_Balance Sheet'!D26+'D1_Balance Sheet'!D32+'D1_Balance Sheet'!D33)/('D1_Balance Sheet'!D26+'D1_Balance Sheet'!D32++'D1_Balance Sheet'!D33+'D1_Balance Sheet'!D42) -> 0.83081171 | E14: =('D1_Balance Sheet'!E26+'D1_Balance Sheet'!E32+'D1_Balance Sheet'!E33)/('D1_Balance Sheet'!E26+'D1_Balance Sheet'!E32++'D1_Balance Sheet'!E33+'D1_Balance Sheet'!E42) -> 0.81615578 | F14: =('D1_Balance Sheet'!F26+'D1_Balance Sheet'!F32+'D1_Balance Sheet'!F33)/('D1_Balance Sheet'!F26+'D1_Balance Sheet'!F32++'D1_Balance Sheet'!F33+'D1_Balance Sheet'!F42) -> 0.79626791 | G14: =('D1_Balance Sheet'!G26+'D1_Balance Sheet'!G32+'D1_Balance Sheet'!G33)/('D1_Balance Sheet'!G26+'D1_Balance Sheet'!G32++'D1_Balance Sheet'!G33+'D1_Balance Sheet'!G42) -> 0.87420533
A15: Financial Leverage | B15: ='D1_Balance Sheet'!B19/'D1_Balance Sheet'!B42 -> 8.0429462 | C15: ='D1_Balance Sheet'!C19/'D1_Balance Sheet'!C42 -> 6.3610126 | D15: ='D1_Balance Sheet'!D19/'D1_Balance Sheet'!D42 -> 6.3897786 | E15: ='D1_Balance Sheet'!E19/'D1_Balance Sheet'!E42 -> 5.9174876 | F15: ='D1_Balance Sheet'!F19/'D1_Balance Sheet'!F42 -> 5.2976154 | G15: ='D1_Balance Sheet'!G19/'D1_Balance Sheet'!G42 -> 8.7084066
B18: Year(t=0) | C18: Year(t=-1) | D18: Year(t=-2) | E18: Year(t=-3) | F18: Year(t=-4) | G18: Year(t=-5)
A19: Solvency Ratios
A20: Debt to Assets | B20: =B13 -> 0.39732328 | C20: =C13 -> 0.37468618 | D20: =D13 -> 0.37148659 | E20: =E13 -> 0.37855434 | F20: =F13 -> 0.35297528 | G20: =G13 -> 0.36365949
A21: Equity to Assets | B21: ='D1_Balance Sheet'!B42/'D1_Balance Sheet'!B19 -> 0.12433255 | C21: ='D1_Balance Sheet'!C42/'D1_Balance Sheet'!C19 -> 0.15720767 | D21: ='D1_Balance Sheet'!D42/'D1_Balance Sheet'!D19 -> 0.15649995 | E21: ='D1_Balance Sheet'!E42/'D1_Balance Sheet'!E19 -> 0.16899064 | F21: ='D1_Balance Sheet'!F42/'D1_Balance Sheet'!F19 -> 0.18876418 | G21: ='D1_Balance Sheet'!G42/'D1_Balance Sheet'!G19 -> 0.11483157
B24: Year(t=0) | C24: Year(t=-1) | D24: Year(t=-2) | E24: Year(t=-3) | F24: Year(t=-4) | G24: Year(t=-5)
A25: Other Ratios
A26: Current Assets to Total Assets | B26: ='D1_Balance Sheet'!B11/'D1_Balance Sheet'!B19 -> 0.42705423 | C26: ='D1_Balance Sheet'!C11/'D1_Balance Sheet'!C19 -> 0.43645072 | D26: ='D1_Balance Sheet'!D11/'D1_Balance Sheet'!D19 -> 0.44448063 | E26: ='D1_Balance Sheet'!E11/'D1_Balance Sheet'!E19 -> 0.45519063 | F26: ='D1_Balance Sheet'!F11/'D1_Balance Sheet'!F19 -> 0.4240512 | G26: ='D1_Balance Sheet'!G11/'D1_Balance Sheet'!G19 -> 0.43681645
A27: Non-current Assets to Total Assets | B27: =('D1_Balance Sheet'!B13+'D1_Balance Sheet'!B14+'D1_Balance Sheet'!B15+'D1_Balance Sheet'!B16+'D1_Balance Sheet'!B17+'D1_Balance Sheet'!B18)/'D1_Balance Sheet'!B19 -> 0.57294577 | C27: =('D1_Balance Sheet'!C13+'D1_Balance Sheet'!C14+'D1_Balance Sheet'!C15+'D1_Balance Sheet'!C16+'D1_Balance Sheet'!C17+'D1_Balance Sheet'!C18)/'D1_Balance Sheet'!C19 -> 0.56354928 | D27: =('D1_Balance Sheet'!D13+'D1_Balance Sheet'!D14+'D1_Balance Sheet'!D15+'D1_Balance Sheet'!D16+'D1_Balance Sheet'!D17+'D1_Balance Sheet'!D18)/'D1_Balance Sheet'!D19 -> 0.55551937 | E27: =('D1_Balance Sheet'!E13+'D1_Balance Sheet'!E14+'D1_Balance Sheet'!E15+'D1_Balance Sheet'!E16+'D1_Balance Sheet'!E17+'D1_Balance Sheet'!E18)/'D1_Balance Sheet'!E19 -> 0.54480937 | F27: =('D1_Balance Sheet'!F13+'D1_Balance Sheet'!F14+'D1_Balance Sheet'!F15+'D1_Balance Sheet'!F16+'D1_Balance Sheet'!F17+'D1_Balance Sheet'!F18)/'D1_Balance Sheet'!F19 -> 0.5759488 | G27: =('D1_Balance Sheet'!G13+'D1_Balance Sheet'!G14+'D1_Balance Sheet'!G15+'D1_Balance Sheet'!G16+'D1_Balance Sheet'!G17+'D1_Balance Sheet'!G18)/'D1_Balance Sheet'!G19 -> 0.56318355
A28: Current Liabilities to Total Liabilities | B28: ='D1_Balance Sheet'!B26/('D1_Balance Sheet'!B43-'D1_Balance Sheet'!B42) -> 0.45373764 | C28: ='D1_Balance Sheet'!C26/('D1_Balance Sheet'!C43-'D1_Balance Sheet'!C42) -> 0.44457712 | D28: ='D1_Balance Sheet'!D26/('D1_Balance Sheet'!D43-'D1_Balance Sheet'!D42) -> 0.44041087 | E28: ='D1_Balance Sheet'!E26/('D1_Balance Sheet'!E43-'D1_Balance Sheet'!E42) -> 0.4555356 | F28: ='D1_Balance Sheet'!F26/('D1_Balance Sheet'!F43-'D1_Balance Sheet'!F42) -> 0.4351081 | G28: ='D1_Balance Sheet'!G26/('D1_Balance Sheet'!G43-'D1_Balance Sheet'!G42) -> 0.41083649
A29: Non-current Liabilities to Total Liaibilities | B29: =('D1_Balance Sheet'!B28+'D1_Balance Sheet'!B29+'D1_Balance Sheet'!B30+'D1_Balance Sheet'!B32+'D1_Balance Sheet'!B33)/('D1_Balance Sheet'!B43-'D1_Balance Sheet'!B42) -> 0.54626236 | C29: =('D1_Balance Sheet'!C28+'D1_Balance Sheet'!C29+'D1_Balance Sheet'!C30+'D1_Balance Sheet'!C32+'D1_Balance Sheet'!C33)/('D1_Balance Sheet'!C43-'D1_Balance Sheet'!C42) -> 0.55542288 | D29: =('D1_Balance Sheet'!D28+'D1_Balance Sheet'!D29+'D1_Balance Sheet'!D30+'D1_Balance Sheet'!D32+'D1_Balance Sheet'!D33)/('D1_Balance Sheet'!D43-'D1_Balance Sheet'!D42) -> 0.55958913 | E29: =('D1_Balance Sheet'!E28+'D1_Balance Sheet'!E29+'D1_Balance Sheet'!E30+'D1_Balance Sheet'!E32+'D1_Balance Sheet'!E33)/('D1_Balance Sheet'!E43-'D1_Balance Sheet'!E42) -> 0.5444644 | F29: =('D1_Balance Sheet'!F28+'D1_Balance Sheet'!F29+'D1_Balance Sheet'!F30+'D1_Balance Sheet'!F32+'D1_Balance Sheet'!F33)/('D1_Balance Sheet'!F43-'D1_Balance Sheet'!F42) -> 0.5648919 | G29: =('D1_Balance Sheet'!G28+'D1_Balance Sheet'!G29+'D1_Balance Sheet'!G30+'D1_Balance Sheet'!G32+'D1_Balance Sheet'!G33)/('D1_Balance Sheet'!G43-'D1_Balance Sheet'!G42) -> 0.58916351
A30: Retained Earnings to Total Equity | B30: ='D1_Balance Sheet'!B40/'D1_Balance Sheet'!B42 -> 0.62605696 | C30: ='D1_Balance Sheet'!C40/'D1_Balance Sheet'!C42 -> 0.75253708 | D30: ='D1_Balance Sheet'!D40/'D1_Balance Sheet'!D42 -> 0.72543427 | E30: ='D1_Balance Sheet'!E40/'D1_Balance Sheet'!E42 -> 0.73433236 | F30: ='D1_Balance Sheet'!F40/'D1_Balance Sheet'!F42 -> 0.73721635 | G30: ='D1_Balance Sheet'!G40/'D1_Balance Sheet'!G42 -> 0.59442815
A31: AOCI to Total Equity | B31: ='D1_Balance Sheet'!B41/'D1_Balance Sheet'!B42 -> -0.2144526 | C31: ='D1_Balance Sheet'!C41/'D1_Balance Sheet'!C42 -> -0.21498829 | D31: ='D1_Balance Sheet'!D41/'D1_Balance Sheet'!D42 -> -0.21139504 | E31: ='D1_Balance Sheet'!E41/'D1_Balance Sheet'!E42 -> -0.21597058 | F31: ='D1_Balance Sheet'!F41/'D1_Balance Sheet'!F42 -> -0.17187081 | G31: ='D1_Balance Sheet'!G41/'D1_Balance Sheet'!G42 -> -0.2702509
A32: Paid-In Capital to Total Equity | B32: ='D1_Balance Sheet'!B37/'D1_Balance Sheet'!B42 -> 0.66538718 | C32: ='D1_Balance Sheet'!C37/'D1_Balance Sheet'!C42 -> 0.52418869 | D32: ='D1_Balance Sheet'!D37/'D1_Balance Sheet'!D42 -> 0.54071494 | E32: ='D1_Balance Sheet'!E37/'D1_Balance Sheet'!E42 -> 0.52800518 | F32: ='D1_Balance Sheet'!F37/'D1_Balance Sheet'!F42 -> 0.46602362 | G32: ='D1_Balance Sheet'!G37/'D1_Balance Sheet'!G42 -> 0.72629521

Sheet D1-4-Place Figures Here
A1: Insert any figures requested in the deliverable instructions here:

Sheet D1_IncomeStatment
A1: Line Items | B1: Year(t=0) | C1: Year(t=-1) | D1: Year(t=-2) | E1: Year(t=-3) | F1: Year(t=-4) | G1: Year(t=-5) | I1: MEAN | J1: STD | K1: MIN | L1: MEDIAN | M1: MAX
B2: 2025 | C2: 2024 | D2: 2023 | E2: 2022 | F2: 2021 | G2: 2020
A3: Revenues
A4: Product Revenues | F4: 126268 | I4: =AVERAGE(B4:G4) -> 126268 | J4: =STDEV(B4:G4) -> #DIV/0! | K4: =MIN(B4:G4) -> 126268 | L4: =MEDIAN(B4:G4) -> 126268 | M4: =MAX(B4:G4) -> 126268
A5: Company excluding Ford Credit | B5: 173996 | C5: 172706 | D5: 165901 | E5: 149079 | I5: =AVERAGE(B5:G5) -> 165420.5 | J5: =STDEV(B5:G5) -> 11458.522 | K5: =MIN(B5:G5) -> 149079 | L5: =MEDIAN(B5:G5) -> 169303.5 | M5: =MAX(B5:G5) -> 173996
A6: Automotive | G6: 115894 | I6: =AVERAGE(B6:G6) -> 115894 | J6: =STDEV(B6:G6) -> #DIV/0! | K6: =MIN(B6:G6) -> 115894 | L6: =MEDIAN(B6:G6) -> 115894 | M6: =MAX(B6:G6) -> 115894
A7: Mobility | G7: 47 | I7: =AVERAGE(B7:G7) -> 47 | J7: =STDEV(B7:G7) -> #DIV/0! | K7: =MIN(B7:G7) -> 47 | L7: =MEDIAN(B7:G7) -> 47 | M7: =MAX(B7:G7) -> 47
A8: Financial Services Revenues | B8: 13271 | C8: 12286 | D8: 10290 | E8: 8978 | F8: 10073 | G8: 11203 | I8: =AVERAGE(B8:G8) -> 11016.833 | J8: =STDEV(B8:G8) -> 1568.6082 | K8: =MIN(B8:G8) -> 8978 | L8: =MEDIAN(B8:G8) -> 10746.5 | M8: =MAX(B8:G8) -> 13271
A9: Total Revenues | B9: 187267 | C9: 184992 | D9: 176191 | E9: 158057 | F9: 136341 | G9: 127144 | I9: =AVERAGE(B9:G9) -> 161665.33 | J9: =STDEV(B9:G9) -> 25521.121 | K9: =MIN(B9:G9) -> 127144 | L9: =MEDIAN(B9:G9) -> 167124 | M9: =MAX(B9:G9) -> 187267
A10: Expenses
A11: Cost of Sales | B11: -150550 | C11: -158434 | D11: -150550 | E11: -134397 | F11: -114651 | G11: -112752 | I11: =AVERAGE(B11:G11) -> -136889 | J11: =STDEV(B11:G11) -> 19599.828 | K11: =MIN(B11:G11) -> -158434 | L11: =MEDIAN(B11:G11) -> -142473.5 | M11: =MAX(B11:G11) -> -112752
A12: Depreciation and Tooling Amortization | B12: -2460 | C12: -2529 | D12: -2589 | E12: -2281 | F12: -1666 | G12: -3269 | I12: =AVERAGE(B12:G12) -> -2465.6667 | J12: =STDEV(B12:G12) -> 517.33303 | K12: =MIN(B12:G12) -> -3269 | L12: =MEDIAN(B12:G12) -> -2494.5 | M12: =MAX(B12:G12) -> -1666
A13: Operating Expenses - Fin. Div. | E13: -881 | F13: -796 | G13: -1936 | I13: =AVERAGE(B13:G13) -> -1204.3333 | J13: =STDEV(B13:G13) -> 635.06561 | K13: =MIN(B13:G13) -> -1936 | L13: =MEDIAN(B13:G13) -> -881 | M13: =MAX(B13:G13) -> -796
A14: Ford Credit Interest, Operating, and Other Expenses | B14: -1634 | C14: -940 | D14: -581 | I14: =AVERAGE(B14:G14) -> -1051.6667 | J14: =STDEV(B14:G14) -> 535.3077 | K14: =MIN(B14:G14) -> -1634 | L14: =MEDIAN(B14:G14) -> -940 | M14: =MAX(B14:G14) -> -581
A15: Selling Administrative and Other Expenses | B15: -10849 | C15: -10287 | D15: -10702 | E15: -10888 | F15: -11915 | G15: -10193 | I15: =AVERAGE(B15:G15) -> -10805.667 | J15: =STDEV(B15:G15) -> 615.53218 | K15: =MIN(B15:G15) -> -11915 | L15: =MEDIAN(B15:G15) -> -10775.5 | M15: =MAX(B15:G15) -> -10193
A16: Interest Expense on Company Debt Excluding Ford Credit | B16: -1254 | C16: -1115 | D16: -1302 | E16: -1259 | F16: -1803 | G16: -1649 | I16: =AVERAGE(B16:G16) -> -1397 | J16: =STDEV(B16:G16) -> 266.9764 | K16: =MIN(B16:G16) -> -1803 | L16: =MEDIAN(B16:G16) -> -1280.5 | M16: =MAX(B16:G16) -> -1115
A17: Interest Expense | B17: -7133 | C17: -7583 | D17: -6311 | E17: -3334 | F17: -2790 | G17: -3402 | I17: =AVERAGE(B17:G17) -> -5092.1667 | J17: =STDEV(B17:G17) -> 2149.5391 | K17: =MIN(B17:G17) -> -7583 | L17: =MEDIAN(B17:G17) -> -4856.5 | M17: =MAX(B17:G17) -> -2790
A18: Equity in Net (Loss)/income of Affiliated Companies | B18: -3153 | C18: 678 | D18: 414 | E18: -2883 | F18: 327 | G18: 42 | I18: =AVERAGE(B18:G18) -> -762.5 | J18: =STDEV(B18:G18) -> 1760.9335 | K18: =MIN(B18:G18) -> -3153 | L18: =MEDIAN(B18:G18) -> 184.5 | M18: =MAX(B18:G18) -> 678
A19: Other Income (Loss), Net | B19: 1746 | C19: 2451 | D19: -603 | E19: -5150 | F19: 14733 | G19: 4899 | I19: =AVERAGE(B19:G19) -> 3012.6667 | J19: =STDEV(B19:G19) -> 6671.5299 | K19: =MIN(B19:G19) -> -5150 | L19: =MEDIAN(B19:G19) -> 2098.5 | M19: =MAX(B19:G19) -> 14733
A20: Income/(Loss) before Income Taxes-financial Services | F20: 4717 | G20: 2608 | I20: =AVERAGE(B20:G20) -> 3662.5 | J20: =STDEV(B20:G20) -> 1491.2882 | K20: =MIN(B20:G20) -> 2608 | L20: =MEDIAN(B20:G20) -> 3662.5 | M20: =MAX(B20:G20) -> 4717
A21: Income (Loss) before Income Taxes | E21: 2657 | I21: =AVERAGE(B21:G21) -> 2657 | J21: =STDEV(B21:G21) -> #DIV/0! | K21: =MIN(B21:G21) -> 2657 | L21: =MEDIAN(B21:G21) -> 2657 | M21: =MAX(B21:G21) -> 2657
A22: Earnings before Taxes | B22: -11830 | C22: 7233 | D22: 3967 | E22: -3016 | F22: 17780 | G22: -1116 | I22: =AVERAGE(B22:G22) -> 2169.6667 | J22: =STDEV(B22:G22) -> 10062.084 | K22: =MIN(B22:G22) -> -11830 | L22: =MEDIAN(B22:G22) -> 1425.5 | M22: =MAX(B22:G22) -> 17780
A23: Taxes and Other Expenses
A24: Provision for Income Tax | B24: 3668 | C24: -1339 | D24: 362 | E24: 864 | F24: 130 | G24: -160 | I24: =AVERAGE(B24:G24) -> 587.5 | J24: =STDEV(B24:G24) -> 1679.0621 | K24: =MIN(B24:G24) -> -1339 | L24: =MEDIAN(B24:G24) -> 246 | M24: =MAX(B24:G24) -> 3668
A25: Minority Interest (After Tax) | B25: -20 | C25: -15 | D25: 18 | E25: 171 | F25: 27 | G25: -3 | I25: =AVERAGE(B25:G25) -> 29.666667 | J25: =STDEV(B25:G25) -> 71.620295 | K25: =MIN(B25:G25) -> -20 | L25: =MEDIAN(B25:G25) -> 7.5 | M25: =MAX(B25:G25) -> 171
A26: Net Income (Loss) | B26: -8182 | C26: 5879 | D26: 4347 | E26: -1981 | F26: 17937 | G26: -1279 | I26: =AVERAGE(B26:G26) -> 2786.8333 | J26: =STDEV(B26:G26) -> 8956.5809 | K26: =MIN(B26:G26) -> -8182 | L26: =MEDIAN(B26:G26) -> 1534 | M26: =MAX(B26:G26) -> 17937
A27: Supplementary Info
A28: Operating Income (Loss) | B28: -9169 | C28: 5219 | D28: 5458 | E28: 6276 | F28: 4523 | G28: -4408 | I28: =AVERAGE(B28:G28) -> 1316.5 | J28: =STDEV(B28:G28) -> 6480.3614 | K28: =MIN(B28:G28) -> -9169 | L28: =MEDIAN(B28:G28) -> 4871 | M28: =MAX(B28:G28) -> 6276
A29: Basic EPS - Continuing Operations | B29: -2.06 | C29: 1.48 | D29: 1.09 | E29: -0.49 | F29: 4.49 | G29: -0.32 | I29: =AVERAGE(B29:G29) -> 0.69833333 | J29: =STDEV(B29:G29) -> 2.2449358 | K29: =MIN(B29:G29) -> -2.06 | L29: =MEDIAN(B29:G29) -> 0.385 | M29: =MAX(B29:G29) -> 4.49
A30: Diluted EPS - Continuing Operations | B30: -2.06 | C30: 1.46 | D30: 1.08 | E30: -0.49 | F30: 4.45 | G30: -0.32 | I30: =AVERAGE(B30:G30) -> 0.68666667 | J30: =STDEV(B30:G30) -> 2.2296876 | K30: =MIN(B30:G30) -> -2.06 | L30: =MEDIAN(B30:G30) -> 0.38 | M30: =MAX(B30:G30) -> 4.45
A31: Share Count | B31: =B26/B30 -> 3971.8447 | C31: =C26/C30 -> 4026.7123 | D31: =D26/D30 -> 4025 | E31: =E26/E30 -> 4042.8571 | F31: =F26/F30 -> 4030.7865 | G31: =G26/G30 -> 3996.875

Sheet D2_IncomeStatmentCommonSize
A1: Line Items | B1: Year(t=0) | C1: Year(t=-1) | D1: Year(t=-2) | E1: Year(t=-3) | F1: Year(t=-4) | G1: Year(t=-5)
B2: 2025 | C2: 2024 | D2: 2023 | E2: 2022 | F2: 2021 | G2: 2020
A3: Revenues | J3: % of revenue = (line item/total rev)
A4: Product Revenues | F4: =D1_IncomeStatment!F4/D1_IncomeStatment!$F$9 -> 0.92611907
