Workbook

Sheet Call Option
B4: This is a project, to price call options, though two equations
B6: Call Option that I am picking will be a Meta call
B8: META Option details:
B9: 3 month Call
B10: Expires Feb 20th
B11: Strike price is 620
B12: Bid-ask spread is 36.95-37.55
B14: Current Meta Stock Price: 594.25
B20: *because yahoo isn't free, I went to Nasdaq and downloaded the daily values, and then I converted it into weekly values, and got the percent change off of that. That is why the rows in Historical data go down to 1200

Sheet Historical data
A1: Date | B1: Close/Last | C1: Week Close | D1: Percent Change
A2: 44159 | B2: 276.92 | C2: =IF(WEEKNUM(A2)<>WEEKNUM(A3),B2,"") | D2: {=IF(C2="","",C2/LOOKUP(2,1/($C$1:C1<>""),$C$1:C1)-1)}
A3: 44160 | B3: 275.59 | C3: =IF(WEEKNUM(A3)<>WEEKNUM(A4),B3,"") | D3: {=IF(C3="","",C3/LOOKUP(2,1/($C$1:C2<>""),$C$1:C2)-1)}
A4: 44162 | B4: 277.81 | C4: =IF(WEEKNUM(A4)<>WEEKNUM(A5),B4,"") -> 277.81 | D4: {=IF(C4="","",C4/LOOKUP(2,1/($C$1:C3<>""),$C$1:C3)-1)} -> #VALUE!
A5: 44165 | B5: 276.97 | C5: =IF(WEEKNUM(A5)<>WEEKNUM(A6),B5,"") | D5: {=IF(C5="","",C5/LOOKUP(2,1/($C$1:C4<>""),$C$1:C4)-1)}
A6: 44166 | B6: 286.55 | C6: =IF(WEEKNUM(A6)<>WEEKNUM(A7),B6,"") | D6: {=IF(C6="","",C6/LOOKUP(2,1/($C$1:C5<>""),$C$1:C5)-1)}
A7: 44167 | B7: 287.52 | C7: =IF(WEEKNUM(A7)<>WEEKNUM(A8),B7,"") | D7: {=IF(C7="","",C7/LOOKUP(2,1/($C$1:C6<>""),$C$1:C6)-1)}
A8: 44168 | B8: 281.85 | C8: =IF(WEEKNUM(A8)<>WEEKNUM(A9),B8,"") | D8: {=IF(C8="","",C8/LOOKUP(2,1/($C$1:C7<>""),$C$1:C7)-1)}
A9: 44169 | B9: 279.7 | C9: =IF(WEEKNUM(A9)<>WEEKNUM(A10),B9,"") -> 279.7 | D9: {=IF(C9="","",C9/LOOKUP(2,1/($C$1:C8<>""),$C$1:C8)-1)} -> 0.0068032108 | F9: Standard Dev: | G9: =_xlfn.STDEV.S(D9:D1256) -> 0.056402941
A10: 44172 | B10: 285.58 | C10: =IF(WEEKNUM(A10)<>WEEKNUM(A11),B10,"") | D10: {=IF(C10="","",C10/LOOKUP(2,1/($C$1:C9<>""),$C$1:C9)-1)}
A11: 44173 | B11: 283.4 | C11: =IF(WEEKNUM(A11)<>WEEKNUM(A12),B11,"") | D11: {=IF(C11="","",C11/LOOKUP(2,1/($C$1:C10<>""),$C$1:C10)-1)}
A12: 44174 | B12: 277.92 | C12: =IF(WEEKNUM(A12)<>WEEKNUM(A13),B12,"") | D12: {=IF(C12="","",C12/LOOKUP(2,1/($C$1:C11<>""),$C$1:C11)-1)}
A13: 44175 | B13: 277.12 | C13: =IF(WEEKNUM(A13)<>WEEKNUM(A14),B13,"") | D13: {=IF(C13="","",C13/LOOKUP(2,1/($C$1:C12<>""),$C$1:C12)-1)}
A14: 44176 | B14: 273.55 | C14: =IF(WEEKNUM(A14)<>WEEKNUM(A15),B14,"") -> 273.55 | D14: {=IF(C14="","",C14/LOOKUP(2,1/($C$1:C13<>""),$C$1:C13)-1)} -> -0.021987844 | F14: Annualized Volatility: | G14: =G9*SQRT(52) -> 0.40672739
A15: 44179 | B15: 274.19 | C15: =IF(WEEKNUM(A15)<>WEEKNUM(A16),B15,"") | D15: {=IF(C15="","",C15/LOOKUP(2,1/($C$1:C14<>""),$C$1:C14)-1)}
A16: 44180 | B16: 275.55 | C16: =IF(WEEKNUM(A16)<>WEEKNUM(A17),B16,"") | D16: {=IF(C16="","",C16/LOOKUP(2,1/($C$1:C15<>""),$C$1:C15)-1)}
A17: 44181 | B17: 275.67 | C17: =IF(WEEKNUM(A17)<>WEEKNUM(A18),B17,"") | D17: {=IF(C17="","",C17/LOOKUP(2,1/($C$1:C16<>""),$C$1:C16)-1)}
A18: 44182 | B18: 274.48 | C18: =IF(WEEKNUM(A18)<>WEEKNUM(A19),B18,"") | D18: {=IF(C18="","",C18/LOOKUP(2,1/($C$1:C17<>""),$C$1:C17)-1)}
A19: 44183 | B19: 276.4 | C19: =IF(WEEKNUM(A19)<>WEEKNUM(A20),B19,"") -> 276.4 | D19: {=IF(C19="","",C19/LOOKUP(2,1/($C$1:C18<>""),$C$1:C18)-1)} -> 0.010418571
A20: 44186 | B20: 272.79 | C20: =IF(WEEKNUM(A20)<>WEEKNUM(A21),B20,"") | D20: {=IF(C20="","",C20/LOOKUP(2,1/($C$1:C19<>""),$C$1:C19)-1)}
A21: 44187 | B21: 267.09 | C21: =IF(WEEKNUM(A21)<>WEEKNUM(A22),B21,"") | D21: {=IF(C21="","",C21/LOOKUP(2,1/($C$1:C20<>""),$C$1:C20)-1)}
A22: 44188 | B22: 268.11 | C22: =IF(WEEKNUM(A22)<>WEEKNUM(A23),B22,"") | D22: {=IF(C22="","",C22/LOOKUP(2,1/($C$1:C21<>""),$C$1:C21)-1)}
A23: 44189 | B23: 267.4 | C23: =IF(WEEKNUM(A23)<>WEEKNUM(A24),B23,"") -> 267.4 | D23: {=IF(C23="","",C23/LOOKUP(2,1/($C$1:C22<>""),$C$1:C22)-1)} -> -0.032561505 | F23: U Factor: | G23: =EXP(G14*SQRT(0.25/2)) -> 1.154653
A24: 44193 | B24: 277 | C24: =IF(WEEKNUM(A24)<>WEEKNUM(A25),B24,"") | D24: {=IF(C24="","",C24/LOOKUP(2,1/($C$1:C23<>""),$C$1:C23)-1)}
A25: 44194 | B25: 276.78 | C25: =IF(WEEKNUM(A25)<>WEEKNUM(A26),B25,"") | D25: {=IF(C25="","",C25/LOOKUP(2,1/($C$1:C24<>""),$C$1:C24)-1)}
A26: 44195 | B26: 271.87 | C26: =IF(WEEKNUM(A26)<>WEEKNUM(A27),B26,"") | D26: {=IF(C26="","",C26/LOOKUP(2,1/($C$1:C25<>""),$C$1:C25)-1)}
A27: 44196 | B27: 273.16 | C27: =IF(WEEKNUM(A27)<>WEEKNUM(A28),B27,"") -> 273.16 | D27: {=IF(C27="","",C27/LOOKUP(2,1/($C$1:C26<>""),$C$1:C26)-1)} -> 0.021540763 | F27: Down Factor: | G27: =1/G23 -> 0.86606108
A28: 44200 | B28: 268.94 | C28: =IF(WEEKNUM(A28)<>WEEKNUM(A29),B28,"") | D28: {=IF(C28="","",C28/LOOKUP(2,1/($C$1:C27<>""),$C$1:C27)-1)}
A29: 44201 | B29: 270.97 | C29: =IF(WEEKNUM(A29)<>WEEKNUM(A30),B29,"") | D29: {=IF(C29="","",C29/LOOKUP(2,1/($C$1:C28<>""),$C$1:C28)-1)}
A30: 44202 | B30: 263.31 | C30: =IF(WEEKNUM(A30)<>WEEKNUM(A31),B30,"") | D30: {=IF(C30="","",C30/LOOKUP(2,1/($C$1:C29<>""),$C$1:C29)-1)}
A31: 44203 | B31: 268.74 | C31: =IF(WEEKNUM(A31)<>WEEKNUM(A32),B31,"") | D31: {=IF(C31="","",C31/LOOKUP(2,1/($C$1:C30<>""),$C$1:C30)-1)}
A32: 44204 | B32: 267.57 | C32: =IF(WEEKNUM(A32)<>WEEKNUM(A33),B32,"") -> 267.57 | D32: {=IF(C32="","",C32/LOOKUP(2,1/($C$1:C31<>""),$C$1:C31)-1)} -> -0.020464197
A33: 44207 | B33: 256.84 | C33: =IF(WEEKNUM(A33)<>WEEKNUM(A34),B33,"") | D33: {=IF(C33="","",C33/LOOKUP(2,1/($C$1:C32<>""),$C$1:C32)-1)}
A34: 44208 | B34: 251.09 | C34: =IF(WEEKNUM(A34)<>WEEKNUM(A35),B34,"") | D34: {=IF(C34="","",C34/LOOKUP(2,1/($C$1:C33<>""),$C$1:C33)-1)}
A35: 44209 | B35: 251.64 | C35: =IF(WEEKNUM(A35)<>WEEKNUM(A36),B35,"") | D35: {=IF(C35="","",C35/LOOKUP(2,1/($C$1:C34<>""),$C$1:C34)-1)}
A36: 44210 | B36: 245.64 | C36: =IF(WEEKNUM(A36)<>WEEKNUM(A37),B36,"") | D36: {=IF(C36="","",C36/LOOKUP(2,1/($C$1:C35<>""),$C$1:C35)-1)}
A37: 44211 | B37: 251.36 | C37: =IF(WEEKNUM(A37)<>WEEKNUM(A38),B37,"") -> 251.36 | D37: {=IF(C37="","",C37/LOOKUP(2,1/($C$1:C36<>""),$C$1:C36)-1)} -> -0.060582278
A38: 44215 | B38: 261.1 | C38: =IF(WEEKNUM(A38)<>WEEKNUM(A39),B38,"") | D38: {=IF(C38="","",C38/LOOKUP(2,1/($C$1:C37<>""),$C$1:C37)-1)}
A39: 44216 | B39: 267.48 | C39: =IF(WEEKNUM(A39)<>WEEKNUM(A40),B39,"") | D39: {=IF(C39="","",C39/LOOKUP(2,1/($C$1:C38<>""),$C$1:C38)-1)}
... A1256: 45982 | B1256: 594.25 | C1256: =IF(WEEKNUM(A1256)<>WEEKNUM(A1257),B1256,"") -> 594.25 | D1256: {=IF(C1256="","",C1256/LOOKUP(2,1/($C$1:C1255<>""),$C$1:C1255)-1)} -> -0.024956519

Sheet Binomial BOPM model
B4: Binomal Model:
B5: Right now, I have:
B6: Stock price= | C6: 594.25
B7: K (strike) = | C7: 620
B8: T = (years) | C8: 0.25
B9: Bid-ask= | C9: =36.95-37.55 -> -0.6
B10: U | C10: ='Historical data'!G23 -> 1.154653
B11: D= | C11: ='Historical data'!G27 -> 0.86606108
B12: Risk free rate= | C12: 0.03834 | D12: 3 month T-bill
B13: Per period risk free rate | C13: =C12 * (C8 / 2) -> 0.0047925
B14: Risk Neutral prob Q: | C14: =((1 + C13) - C11) / (C10 - C11) -> 0.48071835
D18: T=0 | E18: T=1 | F18: T=2 | G18: Call Value t=2 | H18: Call t=1 | I18: Call t=0 | J18: Delta at T=0
C19: Up and then Up | D19: =$C$6 -> 594.25 | E19: =D19 * $C$10 -> 686.15253 | F19: =E19 * $C$10 -> 792.26807 | G19: =MAX(F19 - $C$7, 0) -> 172.26807 | H19: =( $C$14 * G19 + (1 - $C$14) * G20 ) / (1 + $C$13) -> 82.417435 | I19: =( $C$14 * H19 + (1 - $C$14) * H20 ) / (1 + $C$13) -> 39.430603 | J19: =(H19- H20)/(E19 - E20) -> 0.48058008
C20: Up and then Down | E20: =D19 * $C$11 -> 514.65679 | F20: =E19 * $C$11 -> 594.25 | G20: =MAX(F20 - $C$7, 0) -> 0 | H20: =( $C$14 * G20 + (1 - $C$14) * G21 ) / (1 + $C$13) -> 0
C21: Down and Down | F21: =E20 * $C$11 -> 445.72422 | G21: =MAX(F21 - $C$7, 0) -> 0 | H21: 0

Sheet Black Scholes Model
B3: BSM Model
B4: Stock price= | C4: ='Binomial BOPM model'!C6 -> 594.25
B5: K (strike)= | C5: ='Binomial BOPM model'!C7 -> 620
B6: T= | C6: ='Binomial BOPM model'!C8 -> 0.25
B7: Annual Volatility= | C7: ='Historical data'!G14 -> 0.40672739
B8: R (Risk Free Rate)= | C8: ='Binomial BOPM model'!C12 -> 0.03834
B10: D1: | C10: =(LN(C4/C5)+(C8+0.5*C7^2)*C6)/(C7*SQRT(C6)) -> -0.059774562
B11: D2: | C11: =C10 - C7*SQRT(C6) -> -0.26313826
B13: Normal Dist of D1: | C13: =_xlfn.NORM.S.DIST(C10, TRUE) -> 0.47616759
B14: Normal Dist of D2: | C14: =_xlfn.NORM.S.DIST(C11, TRUE) -> 0.39622201
B16: Call Price: | C16: =C4*C13 - C5*EXP(-C8*C6)*C14 -> 39.648326
B36: Theta annual | C36: =-(C4*EXP(-0.5*C10^2)/SQRT(2*PI())*C7)/(2*SQRT(C6))-C8*C5*EXP(-C8*C6)*_xlfn.NORM.S.DIST(C11,TRUE) -> -105.58001 | E36: I used this Formula to get theta:
B37: Theta per day: | C37: =C36/365 -> -0.28926031
B38: per contract: | C38: =C37*100 -> -28.926031 | E38: This means that I am losing 28 dollars per day right now
E39: However, I know that theta speeds up as you get closer to expiration.
E40: I want to build out a theta curve? If possible
C42: Time
B43: TIME
C46: Time | D46: Total Theta for year | E46: Daily Theta | F46: Money Lost due to theta
B47: Time 3 months away | C47: 0.25 | D47: =-( $C$4 * (EXP(-0.5 * ((LN($C$4/$C$5) + ($C$8 + 0.5*$C$7^2)*C47) / ($C$7*SQRT(C47)))^2) / SQRT(2*PI())) * $C$7 ) / (2*SQRT(C47)) - $C$8 * $C$5 * EXP(-$C$8*C47) * _xlfn.NORM.S.DIST(((LN($C$4/$C$5) + ($C$8 + 0.5*$C$7^2)*C47) / ($C$7*SQRT(C47)) - $C$7*SQRT(C47)), TRUE) -> -105.58001 | E47: =D47/365 -> -0.28926031 | F47: =E47*100 -> -28.926031
C48: 0.24 | D48: =-( $C$4 * (EXP(-0.5 * ((LN($C$4/$C$5) + ($C$8 + 0.5*$C$7^2)*C48) / ($C$7*SQRT(C48)))^2) / SQRT(2*PI())) * $C$7 ) / (2*SQRT(C48)) - $C$8 * $C$5 * EXP(-$C$8*C48) * _xlfn.NORM.S.DIST(((LN($C$4/$C$5) + ($C$8 + 0.5*$C$7^2)*C48) / ($C$7*SQRT(C48)) - $C$7*SQRT(C48)), TRUE) -> -107.49381 | E48: =D48/365 -> -0.2945036 | F48: =E48*100 -> -29.45036
C49: =C48-0.01 -> 0.23 | D49: =-( $C$4 * (EXP(-0.5 * ((LN($C$4/$C$5) + ($C$8 + 0.5*$C$7^2)*C49) / ($C$7*SQRT(C49)))^2) / SQRT(2*PI())) * $C$7 ) / (2*SQRT(C49)) - $C$8 * $C$5 * EXP(-$C$8*C49) * _xlfn.NORM.S.DIST(((LN($C$4/$C$5) + ($C$8 + 0.5*$C$7^2)*C49) / ($C$7*SQRT(C49)) - $C$7*SQRT(C49)), TRUE) -> -109.52355 | E49: =D49/365 -> -0.30006452 | F49: =E49*100 -> -30.006452
C50: =C49-0.01 -> 0.22 | D50: =-( $C$4 * (EXP(-0.5 * ((LN($C$4/$C$5) + ($C$8 + 0.5*$C$7^2)*C50) / ($C$7*SQRT(C50)))^2) / SQRT(2*PI())) * $C$7 ) / (2*SQRT(C50)) - $C$8 * $C$5 * EXP(-$C$8*C50) * _xlfn.NORM.S.DIST(((LN($C$4/$C$5) + ($C$8 + 0.5*$C$7^2)*C50) / ($C$7*SQRT(C50)) - $C$7*SQRT(C50)), TRUE) -> -111.68153 | E50: =D50/365 -> -0.30597679 | F50: =E50*100 -> -30.597679
C51: =C50-0.01 -> 0.21 | D51: =-( $C$4 * (EXP(-0.5 * ((LN($C$4/$C$5) + ($C$8 + 0.5*$C$7^2)*C51) / ($C$7*SQRT(C51)))^2) / SQRT(2*PI())) * $C$7 ) / (2*SQRT(C51)) - $C$8 * $C$5 * EXP(-$C$8*C51) * _xlfn.NORM.S.DIST(((LN($C$4/$C$5) + ($C$8 + 0.5*$C$7^2)*C51) / ($C$7*SQRT(C51)) - $C$7*SQRT(C51)), TRUE) -> -113.98198 | E51: =D51/365 -> -0.31227939 | F51: =E51*100 -> -31.227939
C52: =C51-0.01 -> 0.2 | D52: =-( $C$4 * (EXP(-0.5 * ((LN($C$4/$C$5) + ($C$8 + 0.5*$C$7^2)*C52) / ($C$7*SQRT(C52)))^2) / SQRT(2*PI())) * $C$7 ) / (2*SQRT(C52)) - $C$8 * $C$5 * EXP(-$C$8*C52) * _xlfn.NORM.S.DIST(((LN($C$4/$C$5) + ($C$8 + 0.5*$C$7^2)*C52) / ($C$7*SQRT(C52)) - $C$7*SQRT(C52)), TRUE) -> -116.44142 | E52: =D52/365 -> -0.3190176 | F52: =E52*100 -> -31.90176
C53: =C52-0.01 -> 0.19 | D53: =-( $C$4 * (EXP(-0.5 * ((LN($C$4/$C$5) + ($C$8 + 0.5*$C$7^2)*C53) / ($C$7*SQRT(C53)))^2) / SQRT(2*PI())) * $C$7 ) / (2*SQRT(C53)) - $C$8 * $C$5 * EXP(-$C$8*C53) * _xlfn.NORM.S.DIST(((LN($C$4/$C$5) + ($C$8 + 0.5*$C$7^2)*C53) / ($C$7*SQRT(C53)) - $C$7*SQRT(C53)), TRUE) -> -119.07922 | E53: =D53/365 -> -0.32624443 | F53: =E53*100 -> -32.624443
C54: =C53-0.01 -> 0.18 | D54: =-( $C$4 * (EXP(-0.5 * ((LN($C$4/$C$5) + ($C$8 + 0.5*$C$7^2)*C54) / ($C$7*SQRT(C54)))^2) / SQRT(2*PI())) * $C$7 ) / (2*SQRT(C54)) - $C$8 * $C$5 * EXP(-$C$8*C54) * _xlfn.NORM.S.DIST(((LN($C$4/$C$5) + ($C$8 + 0.5*$C$7^2)*C54) / ($C$7*SQRT(C54)) - $C$7*SQRT(C54)), TRUE) -> -121.91815 | E54: =D54/365 -> -0.33402233 | F54: =E54*100 -> -33.402233
C55: =C54-0.01 -> 0.17 | D55: =-( $C$4 * (EXP(-0.5 * ((LN($C$4/$C$5) + ($C$8 + 0.5*$C$7^2)*C55) / ($C$7*SQRT(C55)))^2) / SQRT(2*PI())) * $C$7 ) / (2*SQRT(C55)) - $C$8 * $C$5 * EXP(-$C$8*C55) * _xlfn.NORM.S.DIST(((LN($C$4/$C$5) + ($C$8 + 0.5*$C$7^2)*C55) / ($C$7*SQRT(C55)) - $C$7*SQRT(C55)), TRUE) -> -124.98532 | E55: =D55/365 -> -0.34242553 | F55: =E55*100 -> -34.242553
C56: =C55-0.01 -> 0.16 | D56: =-( $C$4 * (EXP(-0.5 * ((LN($C$4/$C$5) + ($C$8 + 0.5*$C$7^2)*C56) / ($C$7*SQRT(C56)))^2) / SQRT(2*PI())) * $C$7 ) / (2*SQRT(C56)) - $C$8 * $C$5 * EXP(-$C$8*C56) * _xlfn.NORM.S.DIST(((LN($C$4/$C$5) + ($C$8 + 0.5*$C$7^2)*C56) / ($C$7*SQRT(C56)) - $C$7*SQRT(C56)), TRUE) -> -128.31319 | E56: =D56/365 -> -0.35154298 | F56: =E56*100 -> -35.154298
C57: =C56-0.01 -> 0.15 | D57: =-( $C$4 * (EXP(-0.5 * ((LN($C$4/$C$5) + ($C$8 + 0.5*$C$7^2)*C57) / ($C$7*SQRT(C57)))^2) / SQRT(2*PI())) * $C$7 ) / (2*SQRT(C57)) - $C$8 * $C$5 * EXP(-$C$8*C57) * _xlfn.NORM.S.DIST(((LN($C$4/$C$5) + ($C$8 + 0.5*$C$7^2)*C57) / ($C$7*SQRT(C57)) - $C$7*SQRT(C57)), TRUE) -> -131.94107 | E57: =D57/365 -> -0.36148238 | F57: =E57*100 -> -36.148238
C58: =C57-0.01 -> 0.14 | D58: =-( $C$4 * (EXP(-0.5 * ((LN($C$4/$C$5) + ($C$8 + 0.5*$C$7^2)*C58) / ($C$7*SQRT(C58)))^2) / SQRT(2*PI())) * $C$7 ) / (2*SQRT(C58)) - $C$8 * $C$5 * EXP(-$C$8*C58) * _xlfn.NORM.S.DIST(((LN($C$4/$C$5) + ($C$8 + 0.5*$C$7^2)*C58) / ($C$7*SQRT(C58)) - $C$7*SQRT(C58)), TRUE) -> -135.91705 | E58: =D58/365 -> -0.37237549 | F58: =E58*100 -> -37.237549
C59: =C58-0.01 -> 0.13 | D59: =-( $C$4 * (EXP(-0.5 * ((LN($C$4/$C$5) + ($C$8 + 0.5*$C$7^2)*C59) / ($C$7*SQRT(C59)))^2) / SQRT(2*PI())) * $C$7 ) / (2*SQRT(C59)) - $C$8 * $C$5 * EXP(-$C$8*C59) * _xlfn.NORM.S.DIST(((LN($C$4/$C$5) + ($C$8 + 0.5*$C$7^2)*C59) / ($C$7*SQRT(C59)) - $C$7*SQRT(C59)), TRUE) -> -140.3007 | E59: =D59/365 -> -0.38438548 | F59: =E59*100 -> -38.438548
C60: =C59-0.01 -> 0.12 | D60: =-( $C$4 * (EXP(-0.5 * ((LN($C$4/$C$5) + ($C$8 + 0.5*$C$7^2)*C60) / ($C$7*SQRT(C60)))^2) / SQRT(2*PI())) * $C$7 ) / (2*SQRT(C60)) - $C$8 * $C$5 * EXP(-$C$8*C60) * _xlfn.NORM.S.DIST(((LN($C$4/$C$5) + ($C$8 + 0.5*$C$7^2)*C60) / ($C$7*SQRT(C60)) - $C$7*SQRT(C60)), TRUE) -> -145.16677 | E60: =D60/365 -> -0.39771718 | F60: =E60*100 -> -39.771718
... C64: =C63-0.01 -> 0.08 | D64: =-( $C$4 * (EXP(-0.5 * ((LN($C$4/$C$5) + ($C$8 + 0.5*$C$7^2)*C64) / ($C$7*SQRT(C64)))^2) / SQRT(2*PI())) * $C$7 ) / (2*SQRT(C64)) - $C$8 * $C$5 * EXP(-$C$8*C64) * _xlfn.NORM.S.DIST(((LN($C$4/$C$5) + ($C$8 + 0.5*$C$7^2)*C64) / ($C$7*SQRT(C64)) - $C$7*SQRT(C64)), TRUE) -> -171.86045 | E64: =D64/365 -> -0.47085053 | F64: =E64*100 -> -47.085053
C65: =C64-0.01 -> 0.07 | D65: =-( $C$4 * (EXP(-0.5 * ((LN($C$4/$C$5) + ($C$8 + 0.5*$C$7^2)*C65) / ($C$7*SQRT(C65)))^2) / SQRT(2*PI())) * $C$7 ) / (2*SQRT(C65)) - $C$8 * $C$5 * EXP(-$C$8*C65) * _xlfn.NORM.S.DIST(((LN($C$4/$C$5) + ($C$8 + 0.5*$C$7^2)*C65) / ($C$7*SQRT(C65)) - $C$7*SQRT(C65)), TRUE) -> -181.34718 | E65: =D65/365 -> -0.49684158 | F65: =E65*100 -> -49.684158 | J65: I had to flip around the X axis so in the charts case, 0.25 is 3 months away
C66: =C65-0.01 -> 0.06 | D66: =-( $C$4 * (EXP(-0.5 * ((LN($C$4/$C$5) + ($C$8 + 0.5*$C$7^2)*C66) / ($C$7*SQRT(C66)))^2) / SQRT(2*PI())) * $C$7 ) / (2*SQRT(C66)) - $C$8 * $C$5 * EXP(-$C$8*C66) * _xlfn.NORM.S.DIST(((LN($C$4/$C$5) + ($C$8 + 0.5*$C$7^2)*C66) / ($C$7*SQRT(C66)) - $C$7*SQRT(C66)), TRUE) -> -192.66135 | E66: =D66/365 -> -0.52783931 | F66: =E66*100 -> -52.783931
C67: =C66-0.01 -> 0.05 | D67: =-( $C$4 * (EXP(-0.5 * ((LN($C$4/$C$5) + ($C$8 + 0.5*$C$7^2)*C67) / ($C$7*SQRT(C67)))^2) / SQRT(2*PI())) * $C$7 ) / (2*SQRT(C67)) - $C$8 * $C$5 * EXP(-$C$8*C67) * _xlfn.NORM.S.DIST(((LN($C$4/$C$5) + ($C$8 + 0.5*$C$7^2)*C67) / ($C$7*SQRT(C67)) - $C$7*SQRT(C67)), TRUE) -> -206.4402 | E67: =D67/365 -> -0.56558959 | F67: =E67*100 -> -56.558959
C68: =C67-0.01 -> 0.04 | D68: =-( $C$4 * (EXP(-0.5 * ((LN($C$4/$C$5) + ($C$8 + 0.5*$C$7^2)*C68) / ($C$7*SQRT(C68)))^2) / SQRT(2*PI())) * $C$7 ) / (2*SQRT(C68)) - $C$8 * $C$5 * EXP(-$C$8*C68) * _xlfn.NORM.S.DIST(((LN($C$4/$C$5) + ($C$8 + 0.5*$C$7^2)*C68) / ($C$7*SQRT(C68)) - $C$7*SQRT(C68)), TRUE) -> -223.62818 | E68: =D68/365 -> -0.61267994 | F68: =E68*100 -> -61.267994
C69: =C68-0.01 -> 0.03 | D69: =-( $C$4 * (EXP(-0.5 * ((LN($C$4/$C$5) + ($C$8 + 0.5*$C$7^2)*C69) / ($C$7*SQRT(C69)))^2) / SQRT(2*PI())) * $C$7 ) / (2*SQRT(C69)) - $C$8 * $C$5 * EXP(-$C$8*C69) * _xlfn.NORM.S.DIST(((LN($C$4/$C$5) + ($C$8 + 0.5*$C$7^2)*C69) / ($C$7*SQRT(C69)) - $C$7*SQRT(C69)), TRUE) -> -245.54747 | E69: =D69/365 -> -0.6727328 | F69: =E69*100 -> -67.27328
C70: =C69-0.01 -> 0.02 | D70: =-( $C$4 * (EXP(-0.5 * ((LN($C$4/$C$5) + ($C$8 + 0.5*$C$7^2)*C70) / ($C$7*SQRT(C70)))^2) / SQRT(2*PI())) * $C$7 ) / (2*SQRT(C70)) - $C$8 * $C$5 * EXP(-$C$8*C70) * _xlfn.NORM.S.DIST(((LN($C$4/$C$5) + ($C$8 + 0.5*$C$7^2)*C70) / ($C$7*SQRT(C70)) - $C$7*SQRT(C70)), TRUE) -> -273.05399 | E70: =D70/365 -> -0.74809312 | F70: =E70*100 -> -74.809312
...
